Workbook
Name ACTITUD1: [1]Calendario!$B$29
Name ACTITUD2: [1]Calendario!$B$30
Name ACTITUD3: [1]Calendario!$B$31
Name ACTITUD4: [1]Calendario!$B$32
Name ACTITUD5: [1]Calendario!$B$33
Name ACTITUDES: [1]Calendario!$B$28
Name AlAp01: Almnd!$D$4
Name AlAp02: Almnd!$D$5
Name AlAp03: Almnd!$D$6
Name AlAp04: Almnd!$D$7
Name AlAp05: Almnd!$D$8
Name AlAp06: Almnd!$D$9
Name AlAp07: Almnd!$D$10
Name AlAp08: Almnd!$D$11
Name AlAp09: Almnd!$D$12
Name AlAp10: Almnd!$D$13
Name AlAp11: Almnd!$D$14
Name AlAp12: Almnd!$D$15
Name AlAp13: Almnd!$D$16
Name AlAp14: Almnd!$D$17
Name AlAp15: Almnd!$D$18
Name AlAp16: Almnd!$D$19
Name AlAp17: Almnd!$D$20
Name AlAp18: Almnd!$D$21
Name AlAp19: Almnd!$D$22
Name AlAp20: Almnd!$D$23
Name AlAp21: Almnd!$D$24
Name AlAp22: Almnd!$D$25
Name AlAp23: Almnd!$D$26
Name AlAp24: Almnd!$D$27
Name AlAp25: Almnd!$D$28
Name AlAp26: Almnd!$D$29
Name AlAp27: Almnd!$D$30
Name AlAp28: Almnd!$D$31
Name AlAp29: Almnd!$D$32
Name AlAp30: Almnd!$D$33
Name AlCo01: Almnd!$B$4
Name AlCo02: Almnd!$B$5
Name AlCo03: Almnd!$B$6
Name AlCo04: Almnd!$B$7
Name AlCo05: Almnd!$B$8
Name AlCo06: Almnd!$B$9
Name AlCo07: Almnd!$B$10
Name AlCo08: Almnd!$B$11
Name AlCo09: Almnd!$B$12
Name AlCo10: Almnd!$B$13
Name AlCo11: Almnd!$B$14
Name AlCo12: Almnd!$B$15
Name AlCo13: Almnd!$B$16
Name AlCo14: Almnd!$B$17
Name AlCo15: Almnd!$B$18
Name AlCo16: Almnd!$B$19
Name AlCo17: Almnd!$B$20
Name AlCo18: Almnd!$B$21
Name AlCo19: Almnd!$B$22
Name AlCo20: Almnd!$B$23
Name AlCo21: Almnd!$B$24
Name AlCo22: Almnd!$B$25
Name AlCo23: Almnd!$B$26
Name AlCo24: Almnd!$B$27

Sheet UDs
A1: Planificación. Unidades didácticas y prácticas | Q1: =FechaHoy -> 46099
B2: =IModulo&" ("&IProfesor&")" -> FPM-it-1-0237 Infra. comunes de teleco en viviendas y edificios (Rafa Sanz)
B4: Módulo. Centro. Profesorado | F4: Criterios
B6: Datos. Entrada | D6: [Selector] | F6: Criterios de calificación | H6: % CdC | J6: Datos. Salida
C7: Módulo | D7: FPM-it-1-0237 Infra. comunes de teleco en viviendas y edificios | F7: Conocimiento | G7: Contenidos | H7: 0.3 | K7: Nº Tri. | L7: =_xlfn.XLOOKUP(IModulo,Info!$F$4:$F$50,Info!$H$4:$H$50,3) -> 3 | N7: % P.Ev. | O7: 0.15 | Q7: H.Sem. | R7: 5
C8: Centro | D8: IES Ándalan | F8: Procedimiento | G8: Ejercicios | H8: 0.3 | K8: N.UD. | L8: =NUD -> 2 | N8: N.Clase | O8: =MAX(Flts!H14:H349) -> 138 | Q8: H.BOA | R8: {=_xlfn.XLOOKUP(MID(IModulo,1,14),MID(Info!$F$3:$F$50,1,14),Info!$G$3:$G$50,99)} -> 128
C9: Profesorado | D9: Rafa Sanz | F9: Procedimiento | G9: Prácticas | H9: 0.4 | K9: N.Práct. | L9: =NPract -> 3 | N9: H.P.Ev | O9: =R9*PEv -> 20.7 | Q9: H.Real | R9: =HReal -> 138
F10: Actitud | G10: Participación | H10: 0 | Q10: =IF(R10=0,"H.BOA = H.Real","") & IF(R10>0,"H.BOA < H.Real","") & IF(R10<0,"H.BOA > H.Real","") -> H.BOA < H.Real | R10: =HReal-HBOA -> 10
G11: =IF(H11=100%,"¡Ok!. Suma de ponderación 100%","") & IF(H11>100%,"NoOk. Sobra %","") & IF(H11<100%,"NoOk. Falta %","") -> ¡Ok!. Suma de ponderación 100% | H11: =SUM(H7:H10) -> 1
B13: Resultados de aprendizaje
B15: Cód.RA | C15: % Pond. | D15: Resultados de aprendizaje
B16: =IF(ReAp01<>"","RA01","") -> RA01 | C16: 0.15 | D16: RA01 --
B17: =IF(ReAp02<>"","RA02","") -> RA02 | C17: 0.2 | D17: RA02 --
B18: =IF(ReAp03<>"","RA03","") -> RA03 | C18: 0.2 | D18: RA03 --
B19: =IF(ReAp04<>"","RA04","") -> RA04 | C19: 0.2 | D19: RA04 --
B20: =IF(ReAp05<>"","RA05","") -> RA05 | C20: 0.1 | D20: RA05 --
B21: =IF(ReAp06<>"","RA06","") -> RA06 | C21: 0.15 | D21: RA06 --
B22: =IF(ReAp07<>"","RA07","")
B23: =IF(ReAp08<>"","RA08","")
B24: =IF(ReAp09<>"","RA09","")
B25: =IF(ReAp10<>"","RA10","")
B26: =IF(ReAp11<>"","RA11","")
B27: =IF(ReAp12<>"","RA12","")
C28: =SUM(C16:C27) -> 1 | D28: =IF($C$28=100%,"¡Ok!. Suma de ponderación 100%","") & IF($C$28>100%,"NoOk. Sobra %","") & IF($C$28<100%,"NoOk. Falta %","") -> ¡Ok!. Suma de ponderación 100%
B30: Unidades didácticas. Contenidos y Ejercicios
H32: Relación entre RA y Unidades didácticas
B33: Cód.UD | C33: Horas Prv. | D33: Unidades didácticas | E33: Clase Nº. | F33: Fecha Inicio Prevista | G33: Día, Mes Año | H33: =CoRA01 -> RA01 | I33: =CoRA02 -> RA02 | J33: =CoRA03 -> RA03 | K33: =CoRA04 -> RA04 | L33: =CoRA05 -> RA05 | M33: =CoRA06 -> RA06 | N33: =CoRA07 | O33: =CoRA08 | P33: =CoRA09 | Q33: =CoRA10 | R33: =CoRA11 | S33: =CoRA12
B34: =IF(UnDi00<>"","UD00","") -> UD00 | C34: 1 | D34: pw | E34: 1 | F34: =IFERROR(IF(E35<>"",VLOOKUP(B34,Flts!$E$14:$I$349,5,FALSE),""),"") -> 45915 | G34: =IFERROR(MID(Vdias,(WEEKDAY(F34,2)-1)*3+1,3)&", "&MID(Vmeses,(MONTH(F34)-1)*3+1,3)&" "&YEAR(F34),"") -> Lun, Sep 2025
B35: =IF(UnDi01<>"","UD01","") -> UD01 | C35: 34 | D35: ysbu | E35: =IFERROR(IF(E34+C34>E34,E34+C34,""),"") -> 2 | F35: =IFERROR(IF(E36<>"",VLOOKUP(B35,Flts!$E$14:$I$349,5,FALSE),""),"") -> 45916 | G35: =IFERROR(MID(Vdias,(WEEKDAY(F35,2)-1)*3+1,3)&", "&MID(Vmeses,(MONTH(F35)-1)*3+1,3)&" "&YEAR(F35),"") -> Mar, Sep 2025 | H35: X
B36: =IF(UnDi02<>"","UD02","") -> UD02 | C36: 44 | D36: sdfdfasdfdsa | E36: =IFERROR(IF(E35+C35>E35,E35+C35,""),"") -> 36 | F36: =IFERROR(IF(E37<>"",VLOOKUP(B36,Flts!$E$14:$I$349,5,FALSE),""),"") -> 45967 | G36: =IFERROR(MID(Vdias,(WEEKDAY(F36,2)-1)*3+1,3)&", "&MID(Vmeses,(MONTH(F36)-1)*3+1,3)&" "&YEAR(F36),"") -> Jue, Nov 2025 | I36: X | J36: X
B37: =IF(UnDi03<>"","UD03","") | C37: 32 | E37: =IFERROR(IF(E36+C36>E36,E36+C36,""),"") -> 80 | F37: =IFERROR(IF(E38<>"",VLOOKUP(B37,Flts!$E$14:$I$349,5,FALSE),""),"") -> 46048 | G37: =IFERROR(MID(Vdias,(WEEKDAY(F37,2)-1)*3+1,3)&", "&MID(Vmeses,(MONTH(F37)-1)*3+1,3)&" "&YEAR(F37),"") -> Lun, Ene 2026 | J37: X
B38: =IF(UnDi04<>"","UD04","") | C38: 54 | E38: =IFERROR(IF(E37+C37>E37,E37+C37,""),"") -> 112 | F38: =IFERROR(IF(E39<>"",VLOOKUP(B38,Flts!$E$14:$I$349,5,FALSE),""),"") -> 46048 | G38: =IFERROR(MID(Vdias,(WEEKDAY(F38,2)-1)*3+1,3)&", "&MID(Vmeses,(MONTH(F38)-1)*3+1,3)&" "&YEAR(F38),"") -> Lun, Ene 2026 | K38: X
B39: =IF(UnDi05<>"","UD05","") | C39: 24 | E39: =IFERROR(IF(E38+C38>E38,E38+C38,""),"") -> 166 | F39: =IFERROR(IF(E40<>"",VLOOKUP(B39,Flts!$E$14:$I$349,5,FALSE),""),"") -> 46048 | G39: =IFERROR(MID(Vdias,(WEEKDAY(F39,2)-1)*3+1,3)&", "&MID(Vmeses,(MONTH(F39)-1)*3+1,3)&" "&YEAR(F39),"") -> Lun, Ene 2026 | L39: X
B40: =IF(UnDi06<>"","UD06","") | C40: 29 | E40: =IFERROR(IF(E39+C39>E39,E39+C39,""),"") -> 190 | F40: =IFERROR(IF(E41<>"",VLOOKUP(B40,Flts!$E$14:$I$349,5,FALSE),""),"") -> 46048 | G40: =IFERROR(MID(Vdias,(WEEKDAY(F40,2)-1)*3+1,3)&", "&MID(Vmeses,(MONTH(F40)-1)*3+1,3)&" "&YEAR(F40),"") -> Lun, Ene 2026 | M40: X
B41: =IF(UnDi07<>"","UD07","") | E41: =IFERROR(IF(E40+C40>E40,E40+C40,""),"") -> 219 | F41: =IFERROR(IF(E42<>"",VLOOKUP(B41,Flts!$E$14:$I$349,5,FALSE),""),"") | G41: =IFERROR(MID(Vdias,(WEEKDAY(F41,2)-1)*3+1,3)&", "&MID(Vmeses,(MONTH(F41)-1)*3+1,3)&" "&YEAR(F41),"")
B42: =IF(UnDi08<>"","UD08","") | E42: =IFERROR(IF(E41+C41>E41,E41+C41,""),"") | F42: =IFERROR(IF(E43<>"",VLOOKUP(B42,Flts!$E$14:$I$349,5,FALSE),""),"") | G42: =IFERROR(MID(Vdias,(WEEKDAY(F42,2)-1)*3+1,3)&", "&MID(Vmeses,(MONTH(F42)-1)*3+1,3)&" "&YEAR(F42),"")
B43: =IF(UnDi09<>"","UD09","") | E43: =IFERROR(IF(E42+C42>E42,E42+C42,""),"") | F43: =IFERROR(IF(E44<>"",VLOOKUP(B43,Flts!$E$14:$I$349,5,FALSE),""),"") | G43: =IFERROR(MID(Vdias,(WEEKDAY(F43,2)-1)*3+1,3)&", "&MID(Vmeses,(MONTH(F43)-1)*3+1,3)&" "&YEAR(F43),"")
B44: =IF(UnDi10<>"","UD10","") | E44: =IFERROR(IF(E43+C43>E43,E43+C43,""),"") | F44: =IFERROR(IF(E45<>"",VLOOKUP(B44,Flts!$E$14:$I$349,5,FALSE),""),"") | G44: =IFERROR(MID(Vdias,(WEEKDAY(F44,2)-1)*3+1,3)&", "&MID(Vmeses,(MONTH(F44)-1)*3+1,3)&" "&YEAR(F44),"")
B45: =IF(UnDi11<>"","UD11","") | E45: =IFERROR(IF(E44+C44>E44,E44+C44,""),"") | F45: =IFERROR(IF(E46<>"",VLOOKUP(B45,Flts!$E$14:$I$349,5,FALSE),""),"") | G45: =IFERROR(MID(Vdias,(WEEKDAY(F45,2)-1)*3+1,3)&", "&MID(Vmeses,(MONTH(F45)-1)*3+1,3)&" "&YEAR(F45),"")
B46: =IF(UnDi12<>"","UD12","") | E46: =IFERROR(IF(E45+C45>E45,E45+C45,""),"") | F46: =IFERROR(IF(E47<>"",VLOOKUP(B46,Flts!$E$14:$I$349,5,FALSE),""),"") | G46: =IFERROR(MID(Vdias,(WEEKDAY(F46,2)-1)*3+1,3)&", "&MID(Vmeses,(MONTH(F46)-1)*3+1,3)&" "&YEAR(F46),"")
...

Sheet Fchs
A1: ="Fechas. Horario y calendario curso: "&AñoInicioCurso&" - "&AñoInicioCurso+1 -> Fechas. Horario y calendario curso: 2025 - 2026 | N1: =FechaHoy -> 46099
B2: =IModulo&" ("&IProfesor&")" -> FPM-it-1-0237 Infra. comunes de teleco en viviendas y edificios (Rafa Sanz) | O2: https://educa.aragon.es/calendario-escolar
B3: Trimestres
E4: Fechas 1ª. Tri. | H4: Fechas 2ª. Tri. | K4: Fechas 3ª. Tri. | N4: Fechas Ord. y Ext.
B5: Año incio | C5: 2025 | D5: Inicio 1ª. Tri. | E5: 45915 | F5: =MID(Info!$AZ$3,(WEEKDAY(E5,2)-1)*3+1,3) -> Lun | G5: Inicio 2ª Tri. | H5: 45992 | I5: =MID(Info!$AZ$3,(WEEKDAY(H5,2)-1)*3+1,3) -> Lun | J5: Inicio 3ª Tri. | K5: 46097 | L5: =MID(Info!$AZ$3,(WEEKDAY(K5,2)-1)*3+1,3) -> Lun | M5: Inicio FinalOrd. | N5: 46174 | O5: =MID(Info!$AZ$3,(WEEKDAY(N5,2)-1)*3+1,3) -> Lun
B6: Año fin | C6: =AñoInicioCurso+1 -> 2026 | D6: Fin 1ª Tri. | E6: 45989 | F6: =MID(Info!$AZ$3,(WEEKDAY(E6,2)-1)*3+1,3) -> Vie | G6: Fin 2ª Tri. | H6: 46094 | I6: =MID(Info!$AZ$3,(WEEKDAY(H6,2)-1)*3+1,3) -> Vie | J6: Fin 3ª Tri. | K6: 46171 | L6: =MID(Info!$AZ$3,(WEEKDAY(K6,2)-1)*3+1,3) -> Vie | M6: Fin ExtraOrd. | N6: 46195 | O6: =MID(Info!$AZ$3,(WEEKDAY(N6,2)-1)*3+1,3) -> Lun
B7: Días | C7: =SUM(D7:N7) -> 271 | E7: =_xlfn.DAYS(FechaFin1Tri,FechaInicio1Tri) -> 74 | H7: =_xlfn.DAYS(FechaFin2Tri,FechaInicio2Tri) -> 102 | K7: =_xlfn.DAYS(FechaFin3Tri,FechaInicio3Tri) -> 74 | N7: =_xlfn.DAYS(FechaFinEEva,FechaInicioEEva) -> 21 | O7: Días
B9: Ponderación por trimestres | I9: Horario semanal
B10: 1ºCurso = 3Tri., 2ºCurso = 2Tri. | J10: 1 | K10: 2 | L10: 3 | M10: 4 | N10: 5
E11: % Ev. | I11: Nº. Tri. | J11: Lun | K11: Mar | L11: Mié | M11: Jue | N11: Vie | O11: H.Real
B12: Fecha inicio | C12: Fecha fin | D12: Tri. | E12: 2 | F12: 3 | G12: % Tri. | I12: =IF(NTri>2,"3 Tri.","2 Tri.") -> 3 Tri. | J12: 1 | K12: 1 | L12: 1 | M12: 1 | N12: 1 | O12: =SUM(J12:N12) -> 5
A13: 1 | B13: =FechaInicio1Tri -> 45915 | C13: =FechaFin1Tri -> 45989 | D13: 1º Tri. | E13: 0.4 | F13: 0.25 | G13: =_xlfn.XLOOKUP(NTri,$E$12:$F$12,$E13:$F13) -> 0.25 | I13: 1ª Ev. | J13: =SUMIFS(Flts!$AS$14:$AS$349,Flts!$B$14:$B$349,J$11,Flts!$AP$14:$AP$349,"X") -> 9 | K13: =SUMIFS(Flts!$AS$14:$AS$349,Flts!$B$14:$B$349,K$11,Flts!$AP$14:$AP$349,"X") -> 11 | L13: =SUMIFS(Flts!$AS$14:$AS$349,Flts!$B$14:$B$349,L$11,Flts!$AP$14:$AP$349,"X") -> 11 | M13: =SUMIFS(Flts!$AS$14:$AS$349,Flts!$B$14:$B$349,M$11,Flts!$AP$14:$AP$349,"X") -> 11 | N13: =SUMIFS(Flts!$AS$14:$AS$349,Flts!$B$14:$B$349,N$11,Flts!$AP$14:$AP$349,"X") -> 10 | O13: =SUM(J13:N13) -> 52
A14: 2 | B14: =FechaInicio2Tri -> 45992 | C14: =FechaFin2Tri -> 46094 | D14: 2º Tri. | E14: 0.6 | F14: 0.35 | G14: =_xlfn.XLOOKUP(NTri,$E$12:$F$12,$E14:$F14) -> 0.35 | I14: =IF(NTri>2,"2ª Ev.","FinalOrd.") -> 2ª Ev. | J14: =SUMIFS(Flts!$AS$14:$AS$349,Flts!$B$14:$B$349,J$11,Flts!$AQ$14:$AQ$349,"X") -> 7 | K14: =SUMIFS(Flts!$AS$14:$AS$349,Flts!$B$14:$B$349,K$11,Flts!$AQ$14:$AQ$349,"X") -> 8 | L14: =SUMIFS(Flts!$AS$14:$AS$349,Flts!$B$14:$B$349,L$11,Flts!$AQ$14:$AQ$349,"X") -> 9 | M14: =SUMIFS(Flts!$AS$14:$AS$349,Flts!$B$14:$B$349,M$11,Flts!$AQ$14:$AQ$349,"X") -> 8 | N14: =SUMIFS(Flts!$AS$14:$AS$349,Flts!$B$14:$B$349,N$11,Flts!$AQ$14:$AQ$349,"X") -> 8 | O14: =SUM(J14:N14) -> 40
A15: 3 | B15: =IF(NTri=3,FechaInicio3Tri,"") -> 46097 | C15: =IF(NTri=3,FechaFin3Tri,"") -> 46171 | D15: =IF(NTri=3,"3º Tri.","") -> 3º Tri. | E15: 0 | F15: 0.4 | G15: =_xlfn.XLOOKUP(NTri,$E$12:$F$12,$E15:$F15) -> 0.4 | I15: =IF(NTri>2,"FinalOrd.","") -> FinalOrd. | J15: =IF(NTri>2,(SUMIFS(Flts!$AS$14:$AS$349,Flts!$B$14:$B$349,J$11,Flts!$AR$14:$AR$349,"X")),0) -> 9 | K15: =IF(NTri>2,(SUMIFS(Flts!$AS$14:$AS$349,Flts!$B$14:$B$349,K$11,Flts!$AR$14:$AR$349,"X")),0) -> 10 | L15: =IF(NTri>2,(SUMIFS(Flts!$AS$14:$AS$349,Flts!$B$14:$B$349,L$11,Flts!$AR$14:$AR$349,"X")),0) -> 10 | M15: =IF(NTri>2,(SUMIFS(Flts!$AS$14:$AS$349,Flts!$B$14:$B$349,M$11,Flts!$AR$14:$AR$349,"X")),0) -> 9 | N15: =IF(NTri>2,(SUMIFS(Flts!$AS$14:$AS$349,Flts!$B$14:$B$349,N$11,Flts!$AR$14:$AR$349,"X")),0) -> 8 | O15: =IF(NTri=3,SUM(J15:N15),"") -> 46
E16: =SUM(E13:E15) -> 1 | F16: =SUM(F13:F15) -> 1 | G16: =SUM(G13:G15) -> 1 | J16: =SUM(J13:J15) -> 25 | K16: =SUM(K13:K15) -> 29 | L16: =SUM(L13:L15) -> 30 | M16: =SUM(M13:M15) -> 28 | N16: =SUM(N13:N15) -> 26 | O16: =SUM(O13:O15) -> 138
B18: Unidades didácticas. Contenidos (Conocimiento) | I18: Prácticas. Informes técnicos (Procedimiento)
B20: UD | C20: Unidades didácticas | E20: Fecha Prev. | F20: Día, Mes Año | G20: Horas Prev. | I20: Práctica/UD. | J20: Prácticas | M20: Fecha Prev. | N20: Día, Mes Año | O20: Horas Prev.
B21: =CoUD00 -> UD00 | C21: =UnDi00 -> pw | E21: =UDs!F34 -> 45915 | F21: =UDs!G34 -> Lun, Sep 2025 | G21: =UDs!C34 -> 1 | I21: =IF(UDs!D62<>"",UDs!B62&" / "&UDs!E62,"") -> Pr01 / UD01 | J21: =Pract01 -> aasds | M21: =UDs!F62 -> 45916 | N21: =UDs!G62 -> Mar, Sep 2025 | O21: =UDs!C62 -> 4
B22: =CoUD01 -> UD01 | C22: =UnDi01 -> ysbu | E22: =UDs!F35 -> 45916 | F22: =UDs!G35 -> Mar, Sep 2025 | G22: =UDs!C35 -> 34 | I22: =IF(UDs!D63<>"",UDs!B63&" / "&UDs!E63,"") -> Pr02 / UD02 | J22: =Pract02 -> DSDSSDASDA | M22: =UDs!F63 -> 45967 | N22: =UDs!G63 -> Jue, Nov 2025 | O22: =UDs!C63 -> 7
B23: =CoUD02 -> UD02 | C23: =UnDi02 -> sdfdfasdfdsa | E23: =UDs!F36 -> 45967 | F23: =UDs!G36 -> Jue, Nov 2025 | G23: =UDs!C36 -> 44 | I23: =IF(UDs!D64<>"",UDs!B64&" / "&UDs!E64,"") -> Pr03 / UD02 | J23: =Pract03 -> jkljkl | M23: =UDs!F64 -> 45967 | N23: =UDs!G64 -> Jue, Nov 2025 | O23: =UDs!C64 -> 4
B24: =CoUD03 | C24: =UnDi03 -> 0 | E24: =UDs!F37 -> 46048 | F24: =UDs!G37 -> Lun, Ene 2026 | G24: =UDs!C37 -> 32 | I24: =IF(UDs!D65<>"",UDs!B65&" / "&UDs!E65,"") | J24: =Pract04 -> 0 | M24: =UDs!F65 | N24: =UDs!G65 | O24: =UDs!C65 -> 0
B25: =CoUD04 | C25: =UnDi04 -> 0 | E25: =UDs!F38 -> 46048 | F25: =UDs!G38 -> Lun, Ene 2026 | G25: =UDs!C38 -> 54 | I25: =IF(UDs!D66<>"",UDs!B66&" / "&UDs!E66,"") | J25: =Pract05 -> 0 | M25: =UDs!F66 | N25: =UDs!G66 | O25: =UDs!C66 -> 0
B26: =CoUD05 | C26: =UnDi05 -> 0 | E26: =UDs!F39 -> 46048 | F26: =UDs!G39 -> Lun, Ene 2026 | G26: =UDs!C39 -> 24 | I26: =IF(UDs!D67<>"",UDs!B67&" / "&UDs!E67,"") | J26: =Pract06 -> 0 | M26: =UDs!F67 | N26: =UDs!G67 | O26: =UDs!C67 -> 0
B27: =CoUD06 | C27: =UnDi06 -> 0 | E27: =UDs!F40 -> 46048 | F27: =UDs!G40 -> Lun, Ene 2026 | G27: =UDs!C40 -> 29 | I27: =IF(UDs!D68<>"",UDs!B68&" / "&UDs!E68,"") | J27: =Pract07 -> 0 | M27: =UDs!F68 | N27: =UDs!G68 | O27: =UDs!C68 -> 0
B28: =CoUD07 | C28: =UnDi07 -> 0 | E28: =UDs!F41 | F28: =UDs!G41 | G28: =UDs!C41 -> 0 | I28: =IF(UDs!D69<>"",UDs!B69&" / "&UDs!E69,"") | J28: =Pract08 -> 0 | M28: =UDs!F69 | N28: =UDs!G69 | O28: =UDs!C69 -> 0
B29: =CoUD08 | C29: =UnDi08 -> 0 | E29: =UDs!F42 | F29: =UDs!G42 | G29: =UDs!C42 -> 0 | I29: =IF(UDs!D70<>"",UDs!B70&" / "&UDs!E70,"") | J29: =Pract09 -> 0 | M29: =UDs!F70 | N29: =UDs!G70 | O29: =UDs!C70 -> 0
B30: =CoUD09 | C30: =UnDi09 -> 0 | E30: =UDs!F43 | F30: =UDs!G43 | G30: =UDs!C43 -> 0 | I30: =IF(UDs!D71<>"",UDs!B71&" / "&UDs!E71,"") | J30: =Pract10 -> 0 | M30: =UDs!F71 | N30: =UDs!G71 | O30: =UDs!C71 -> 0
B31: =CoUD10 | C31: =UnDi10 -> 0 | E31: =UDs!F44 | F31: =UDs!G44 | G31: =UDs!C44 -> 0 | I31: =IF(UDs!D72<>"",UDs!B72&" / "&UDs!E72,"") | J31: =Pract11 -> 0 | M31: =UDs!F72 | N31: =UDs!G72 | O31: =UDs!C72 -> 0
B32: =CoUD11 | C32: =UnDi11 -> 0 | E32: =UDs!F45 | F32: =UDs!G45 | G32: =UDs!C45 -> 0 | I32: =IF(UDs!D73<>"",UDs!B73&" / "&UDs!E73,"") | J32: =Pract12 -> 0 | M32: =UDs!F73 | N32: =UDs!G73 | O32: =UDs!C73 -> 0
B33: =CoUD12 | C33: =UnDi12 -> 0 | E33: =UDs!F46 | F33: =UDs!G46 | G33: =UDs!C46 -> 0 | I33: =IF(UDs!D74<>"",UDs!B74&" / "&UDs!E74,"") | J33: =Pract13 -> 0 | M33: =UDs!F74 | N33: =UDs!G74 | O33: =UDs!C74 -> 0
B34: =CoUD13 | C34: =UnDi13 -> 0 | E34: =UDs!F47 | F34: =UDs!G47 | G34: =UDs!C47 -> 0 | I34: =IF(UDs!D75<>"",UDs!B75&" / "&UDs!E75,"") | J34: =Pract14 -> 0 | M34: =UDs!F75 | N34: =UDs!G75 | O34: =UDs!C75 -> 0
B35: =CoUD14 | C35: =UnDi14 -> 0 | E35: =UDs!F48 | F35: =UDs!G48 | G35: =UDs!C48 -> 0 | I35: =IF(UDs!D76<>"",UDs!B76&" / "&UDs!E76,"") | J35: =Pract15 -> 0 | M35: =UDs!F76 | N35: =UDs!G76 | O35: =UDs!C76 -> 0
B36: =CoUD15 | C36: =UnDi15 -> 0 | E36: =UDs!F49 | F36: =UDs!G49 | G36: =UDs!C49 -> 0 | I36: =IF(UDs!D77<>"",UDs!B77&" / "&UDs!E77,"") | J36: =Pract16 -> 0 | M36: =UDs!F77 | N36: =UDs!G77 | O36: =UDs!C77 -> 0
B37: =CoUD16 | C37: =UnDi16 -> 0 | E37: =UDs!F50 | F37: =UDs!G50 | G37: =UDs!C50 -> 0 | I37: =IF(UDs!D78<>"",UDs!B78&" / "&UDs!E78,"") | J37: =Pract17 -> 0 | M37: =UDs!F78 | N37: =UDs!G78 | O37: =UDs!C78 -> 0
B38: =CoUD17 | C38: =UnDi17 -> 0 | E38: =UDs!F51 | F38: =UDs!G51 | G38: =UDs!C51 -> 0 | I38: =IF(UDs!D79<>"",UDs!B79&" / "&UDs!E79,"") | J38: =Pract18 -> 0 | M38: =UDs!F79 | N38: =UDs!G79 | O38: =UDs!C79 -> 0
B39: =CoUD18 | C39: =UnDi18 -> 0 | E39: =UDs!F52 | F39: =UDs!G52 | G39: =UDs!C52 -> 0 | I39: =IF(UDs!D80<>"",UDs!B80&" / "&UDs!E80,"") | J39: =Pract19 -> 0 | M39: =UDs!F80 | N39: =UDs!G80 | O39: =UDs!C80 -> 0
B40: =CoUD19 | C40: =UnDi19 -> 0 | E40: =UDs!F53 | F40: =UDs!G53 | G40: =UDs!C53 -> 0 | I40: =IF(UDs!D81<>"",UDs!B81&" / "&UDs!E81,"") | J40: =Pract20 -> 0 | M40: =UDs!F81 | N40: =UDs!G81 | O40: =UDs!C81 -> 0
B41: =CoUD20 | C41: =UnDi20 -> 0 | E41: =UDs!F54 | F41: =UDs!G54 | G41: =UDs!C54 -> 0 | I41: =IF(UDs!D82<>"",UDs!B82&" / "&UDs!E82,"") | J41: =Pract21 -> 0 | M41: =UDs!F82 | N41: =UDs!G82 | O41: =UDs!C82 -> 0
B42: =CoUDCM -> NoOk | F42: =UnDiCM -> NoOk ¡Atención! Falta/n -80 hora/s | G42: =UDs!C55 -> -80 | I42: =IF(UDs!D83<>"",UDs!B83&" / "&UDs!E83,"") | J42: =Pract22 -> 0 | M42: =UDs!F83 | N42: =UDs!G83 | O42: =UDs!C83 -> 0
I43: =IF(UDs!D84<>"",UDs!B84&" / "&UDs!E84,"") | J43: =Pract23 -> 0 | M43: =UDs!F84 | N43: =UDs!G84 | O43: =UDs!C84 -> 0
...

Sheet Sgmt
A1: Seguimiento. Unidades didácticas. Contingencias | Y1: =FechaHoy -> 46099
B2: =IModulo&" ("&IProfesor&")" -> FPM-it-1-0237 Infra. comunes de teleco en viviendas y edificios (Rafa Sanz)
B3: Unidades didácticas
AC4: Fechas 'De hoy' o 'Simulada'
D5: 1er Tri. | H5: =D29+F29+H29+J29 -> 66 | I5: =E29+G29+I29+K29 -> 66 | J5: =(E29+G29+I29+K29)/(D29+F29+H29+J29) -> 1 | L5: 2º Tri. | N5: =L29+N29+P29 -> 427 | O5: =M29+O29+Q29 -> 301 | P5: =(M29+O29+Q29)/(L29+N29+P29) -> 0.70491803 | R5: 3er Tri. | T5: =R29+T29+V29 -> 648 | U5: =S29+U29+W29 -> 0 | V5: =IF(NTri>=$R$30,(S29+U29+W29)/(R29+T29+V29),"") -> 0 | AC5: =Info!W3 -> De hoy | AD5: =TODAY() -> 46099
D6: Sep | F6: Oct | H6: Nov | J6: Dic | L6: Ene | N6: Feb | P6: Mar | R6: Abr | T6: May | V6: Jun | Y6: Trimestres | AC6: =Info!W4 -> Simulada | AD6: 45536
B7: Cód.UD | C7: Hora clase | D7: Prv. | E7: Imp. | F7: Prv. | G7: Imp. | H7: Prv. | I7: Imp. | J7: Prv. | K7: Imp. | L7: Prv. | M7: Imp. | N7: Prv. | O7: Imp. | P7: Prv. | Q7: Imp. | R7: Prv. | S7: Imp. | T7: Prv. | U7: Imp. | V7: Prv. | W7: Imp. | X7: Horas Imp. | Y7: 1er. | Z7: 2º. | AA7: 3er. | AC7: Selector | AD7: De hoy
B8: =IF(UDs!C34<>0,UDs!B34,IF(C8<>0,CoUDCM,0)) -> UD00 | C8: 1 | D8: =SUMIF(Flts!E$14:E$43,UDs!$B34,Flts!$AS$14:$AS$43) -> 1 | E8: =SUMIF(Flts!F$14:F$43,UDs!$B34,Flts!$AS$14:$AS$43) -> 1 | F8: =SUMIF(Flts!E$48:E$78,UDs!$B34,Flts!$AS$48:$AS$78) -> 0 | G8: =SUMIF(Flts!F$48:F$78,UDs!$B34,Flts!$AS$48:$AS$78) -> 0 | H8: =SUMIF(Flts!E$82:E$111,UDs!$B34,Flts!$AS$82:$AS$111) -> 0 | I8: =SUMIF(Flts!F$82:F$111,UDs!$B34,Flts!$AS$82:$AS$111) -> 0 | J8: =SUMIF(Flts!E$116:E$146,UDs!$B34,Flts!$AS$116:$AS$146) -> 0 | K8: =SUMIF(Flts!F$116:F$146,UDs!$B34,Flts!$AS$116:$AS$146) -> 0 | L8: =SUMIF(Flts!E$150:E$180,UDs!$B34,Flts!$AS$150:$AS$180) -> 0 | M8: =SUMIF(Flts!F$150:F$180,UDs!$B34,Flts!$AS$150:$AS$180) -> 0 | N8: =SUMIF(Flts!E$184:E$212,UDs!$B34,Flts!$AS$184:$AS$212) -> 0 | O8: =SUMIF(Flts!F$184:F$212,UDs!$B34,Flts!$AS$184:$AS$212) -> 0 | P8: =SUMIF(Flts!E$218:E$248,UDs!$B34,Flts!$AS$218:$AS$248) -> 0 | Q8: =SUMIF(Flts!F$218:F$248,UDs!$B34,Flts!$AS$218:$AS$248) -> 0 | R8: =IF(NTri>=$R$30,SUMIF(Flts!E$252:E$281,UDs!$B34,Flts!$AS$252:$AS$281),0) -> 0 | S8: =IF(NTri>=$R$30,SUMIF(Flts!F$252:F$281,UDs!$B34,Flts!$AS$252:$AS$281),0) -> 0 | T8: =IF(NTri>=$R$30,SUMIF(Flts!E$286:E$316,UDs!$B34,Flts!$AS$286:$AS$316),0) -> 0 | U8: =IF(NTri>=$R$30,SUMIF(Flts!F$286:F$316,UDs!$B34,Flts!$AS$286:$AS$316),0) -> 0 | V8: =IF(NTri>=$R$30,SUMIF(Flts!E$320:E$349,UDs!$B34,Flts!$AS$320:$AS$349),0) -> 0 | W8: =IF(NTri>=$R$30,SUMIF(Flts!F$320:F$349,UDs!$B34,Flts!$AS$320:$AS$349),0) -> 0 | X8: =SUM(E8,G8,I8,K8,M8,O8,Q8,S8,U8,W8) -> 1 | Y8: =IF(AND(FechaInicio1Tri<=UDs!$F34, FechaFin1Tri>=UDs!$F34),(E8+G8+I8+K8)/(D8+F8+H8+J8),0%) -> 1 | Z8: =IF(AND(FechaInicio2Tri<=UDs!$F34, FechaFin2Tri>=UDs!$F34),(M8+O8+Q8)/(L8+N8+P8),0%) -> 0 | AA8: =IF(AND(FechaInicio3Tri<=UDs!$F34, FechaFin3Tri>=UDs!$F34),(S8+U8+W8)/(R8+T8+V8),0%) -> 0 | AC8: ="= "&IF(AD7=Info!W4,Info!W4,Info!W3) -> = De hoy | AD8: =IF(AD7=Info!W4,AD6,TODAY()) -> 46099
B9: =IF(UDs!C35<>0,UDs!B35,IF(C9<>0,CoUDCM,0)) -> UD01 | C9: =IFERROR(IF(C8+UDs!C34>C8,C8+UDs!C34,0),0) -> 2 | D9: =SUMIF(Flts!E$14:E$43,UDs!$B35,Flts!$AS$14:$AS$43) -> 11 | E9: =SUMIF(Flts!F$14:F$43,UDs!$B35,Flts!$AS$14:$AS$43) -> 11 | F9: =SUMIF(Flts!E$48:E$78,UDs!$B35,Flts!$AS$48:$AS$78) -> 21 | G9: =SUMIF(Flts!F$48:F$78,UDs!$B35,Flts!$AS$48:$AS$78) -> 21 | H9: =SUMIF(Flts!E$82:E$111,UDs!$B35,Flts!$AS$82:$AS$111) -> 2 | I9: =SUMIF(Flts!F$82:F$111,UDs!$B35,Flts!$AS$82:$AS$111) -> 2 | J9: =SUMIF(Flts!E$116:E$146,UDs!$B35,Flts!$AS$116:$AS$146) -> 0 | K9: =SUMIF(Flts!F$116:F$146,UDs!$B35,Flts!$AS$116:$AS$146) -> 0 | L9: =SUMIF(Flts!E$150:E$180,UDs!$B35,Flts!$AS$150:$AS$180) -> 0 | M9: =SUMIF(Flts!F$150:F$180,UDs!$B35,Flts!$AS$150:$AS$180) -> 0 | N9: =SUMIF(Flts!E$184:E$212,UDs!$B35,Flts!$AS$184:$AS$212) -> 0 | O9: =SUMIF(Flts!F$184:F$212,UDs!$B35,Flts!$AS$184:$AS$212) -> 0 | P9: =SUMIF(Flts!E$218:E$248,UDs!$B35,Flts!$AS$218:$AS$248) -> 0 | Q9: =SUMIF(Flts!F$218:F$248,UDs!$B35,Flts!$AS$218:$AS$248) -> 0 | R9: =IF(NTri>=$R$30,SUMIF(Flts!E$252:E$281,UDs!$B35,Flts!$AS$252:$AS$281),0) -> 0 | S9: =IF(NTri>=$R$30,SUMIF(Flts!F$252:F$281,UDs!$B35,Flts!$AS$252:$AS$281),0) -> 0 | T9: =IF(NTri>=$R$30,SUMIF(Flts!E$286:E$316,UDs!$B35,Flts!$AS$286:$AS$316),0) -> 0 | U9: =IF(NTri>=$R$30,SUMIF(Flts!F$286:F$316,UDs!$B35,Flts!$AS$286:$AS$316),0) -> 0 | V9: =IF(NTri>=$R$30,SUMIF(Flts!E$320:E$349,UDs!$B35,Flts!$AS$320:$AS$349),0) -> 0 | W9: =IF(NTri>=$R$30,SUMIF(Flts!F$320:F$349,UDs!$B35,Flts!$AS$320:$AS$349),0) -> 0 | X9: =SUM(E9,G9,I9,K9,M9,O9,Q9,S9,U9,W9) -> 34 | Y9: =IF(AND(FechaInicio1Tri<=UDs!$F35, FechaFin1Tri>=UDs!$F35),(E9+G9+I9+K9)/(D9+F9+H9+J9),0%) -> 1 | Z9: =IF(AND(FechaInicio2Tri<=UDs!$F35, FechaFin2Tri>=UDs!$F35),(M9+O9+Q9)/(L9+N9+P9),0%) -> 0 | AA9: =IF(AND(FechaInicio3Tri<=UDs!$F35, FechaFin3Tri>=UDs!$F35),(S9+U9+W9)/(R9+T9+V9),0%) -> 0
B10: =IF(UDs!C36<>0,UDs!B36,IF(C10<>0,CoUDCM,0)) -> UD02 | C10: =IFERROR(IF(C9+UDs!C35>C9,C9+UDs!C35,0),0) -> 36 | D10: =SUMIF(Flts!E$14:E$43,UDs!$B36,Flts!$AS$14:$AS$43) -> 0 | E10: =SUMIF(Flts!F$14:F$43,UDs!$B36,Flts!$AS$14:$AS$43) -> 0 | F10: =SUMIF(Flts!E$48:E$78,UDs!$B36,Flts!$AS$48:$AS$78) -> 0 | G10: =SUMIF(Flts!F$48:F$78,UDs!$B36,Flts!$AS$48:$AS$78) -> 0 | H10: =SUMIF(Flts!E$82:E$111,UDs!$B36,Flts!$AS$82:$AS$111) -> 17 | I10: =SUMIF(Flts!F$82:F$111,UDs!$B36,Flts!$AS$82:$AS$111) -> 17 | J10: =SUMIF(Flts!E$116:E$146,UDs!$B36,Flts!$AS$116:$AS$146) -> 14 | K10: =SUMIF(Flts!F$116:F$146,UDs!$B36,Flts!$AS$116:$AS$146) -> 14 | L10: =SUMIF(Flts!E$150:E$180,UDs!$B36,Flts!$AS$150:$AS$180) -> 13 | M10: =SUMIF(Flts!F$150:F$180,UDs!$B36,Flts!$AS$150:$AS$180) -> 13 | N10: =SUMIF(Flts!E$184:E$212,UDs!$B36,Flts!$AS$184:$AS$212) -> 0 | O10: =SUMIF(Flts!F$184:F$212,UDs!$B36,Flts!$AS$184:$AS$212) -> 0 | P10: =SUMIF(Flts!E$218:E$248,UDs!$B36,Flts!$AS$218:$AS$248) -> 0 | Q10: =SUMIF(Flts!F$218:F$248,UDs!$B36,Flts!$AS$218:$AS$248) -> 0 | R10: =IF(NTri>=$R$30,SUMIF(Flts!E$252:E$281,UDs!$B36,Flts!$AS$252:$AS$281),0) -> 0 | S10: =IF(NTri>=$R$30,SUMIF(Flts!F$252:F$281,UDs!$B36,Flts!$AS$252:$AS$281),0) -> 0 | T10: =IF(NTri>=$R$30,SUMIF(Flts!E$286:E$316,UDs!$B36,Flts!$AS$286:$AS$316),0) -> 0 | U10: =IF(NTri>=$R$30,SUMIF(Flts!F$286:F$316,UDs!$B36,Flts!$AS$286:$AS$316),0) -> 0 | V10: =IF(NTri>=$R$30,SUMIF(Flts!E$320:E$349,UDs!$B36,Flts!$AS$320:$AS$349),0) -> 0 | W10: =IF(NTri>=$R$30,SUMIF(Flts!F$320:F$349,UDs!$B36,Flts!$AS$320:$AS$349),0) -> 0 | X10: =SUM(E10,G10,I10,K10,M10,O10,Q10,S10,U10,W10) -> 44 | Y10: =IF(AND(FechaInicio1Tri<=UDs!$F36, FechaFin1Tri>=UDs!$F36),(E10+G10+I10+K10)/(D10+F10+H10+J10),0%) -> 1 | Z10: =IF(AND(FechaInicio2Tri<=UDs!$F36, FechaFin2Tri>=UDs!$F36),(M10+O10+Q10)/(L10+N10+P10),0%) -> 0 | AA10: =IF(AND(FechaInicio3Tri<=UDs!$F36, FechaFin3Tri>=UDs!$F36),(S10+U10+W10)/(R10+T10+V10),0%) -> 0
B11: =IF(UDs!C37<>0,UDs!B37,IF(C11<>0,CoUDCM,0)) | C11: =IFERROR(IF(C10+UDs!C36>C10,C10+UDs!C36,0),0) -> 80 | D11: =SUMIF(Flts!E$14:E$43,UDs!$B37,Flts!$AS$14:$AS$43) -> 0 | E11: =SUMIF(Flts!F$14:F$43,UDs!$B37,Flts!$AS$14:$AS$43) -> 0 | F11: =SUMIF(Flts!E$48:E$78,UDs!$B37,Flts!$AS$48:$AS$78) -> 0 | G11: =SUMIF(Flts!F$48:F$78,UDs!$B37,Flts!$AS$48:$AS$78) -> 0 | H11: =SUMIF(Flts!E$82:E$111,UDs!$B37,Flts!$AS$82:$AS$111) -> 0 | I11: =SUMIF(Flts!F$82:F$111,UDs!$B37,Flts!$AS$82:$AS$111) -> 0 | J11: =SUMIF(Flts!E$116:E$146,UDs!$B37,Flts!$AS$116:$AS$146) -> 0 | K11: =SUMIF(Flts!F$116:F$146,UDs!$B37,Flts!$AS$116:$AS$146) -> 0 | L11: =SUMIF(Flts!E$150:E$180,UDs!$B37,Flts!$AS$150:$AS$180) -> 4 | M11: =SUMIF(Flts!F$150:F$180,UDs!$B37,Flts!$AS$150:$AS$180) -> 4 | N11: =SUMIF(Flts!E$184:E$212,UDs!$B37,Flts!$AS$184:$AS$212) -> 0 | O11: =SUMIF(Flts!F$184:F$212,UDs!$B37,Flts!$AS$184:$AS$212) -> 0 | P11: =SUMIF(Flts!E$218:E$248,UDs!$B37,Flts!$AS$218:$AS$248) -> 19 | Q11: =SUMIF(Flts!F$218:F$248,UDs!$B37,Flts!$AS$218:$AS$248) -> 12 | R11: =IF(NTri>=$R$30,SUMIF(Flts!E$252:E$281,UDs!$B37,Flts!$AS$252:$AS$281),0) -> 16 | S11: =IF(NTri>=$R$30,SUMIF(Flts!F$252:F$281,UDs!$B37,Flts!$AS$252:$AS$281),0) -> 0 | T11: =IF(NTri>=$R$30,SUMIF(Flts!E$286:E$316,UDs!$B37,Flts!$AS$286:$AS$316),0) -> 20 | U11: =IF(NTri>=$R$30,SUMIF(Flts!F$286:F$316,UDs!$B37,Flts!$AS$286:$AS$316),0) -> 0 | V11: =IF(NTri>=$R$30,SUMIF(Flts!E$320:E$349,UDs!$B37,Flts!$AS$320:$AS$349),0) -> 0 | W11: =IF(NTri>=$R$30,SUMIF(Flts!F$320:F$349,UDs!$B37,Flts!$AS$320:$AS$349),0) -> 0 | X11: =SUM(E11,G11,I11,K11,M11,O11,Q11,S11,U11,W11) -> 16 | Y11: =IF(AND(FechaInicio1Tri<=UDs!$F37, FechaFin1Tri>=UDs!$F37),(E11+G11+I11+K11)/(D11+F11+H11+J11),0%) -> 0 | Z11: =IF(AND(FechaInicio2Tri<=UDs!$F37, FechaFin2Tri>=UDs!$F37),(M11+O11+Q11)/(L11+N11+P11),0%) -> 0.69565217 | AA11: =IF(AND(FechaInicio3Tri<=UDs!$F37, FechaFin3Tri>=UDs!$F37),(S11+U11+W11)/(R11+T11+V11),0%) -> 0
B12: =IF(UDs!C38<>0,UDs!B38,IF(C12<>0,CoUDCM,0)) | C12: =IFERROR(IF(C11+UDs!C37>C11,C11+UDs!C37,0),0) -> 112 | D12: =SUMIF(Flts!E$14:E$43,UDs!$B38,Flts!$AS$14:$AS$43) -> 0 | E12: =SUMIF(Flts!F$14:F$43,UDs!$B38,Flts!$AS$14:$AS$43) -> 0 | F12: =SUMIF(Flts!E$48:E$78,UDs!$B38,Flts!$AS$48:$AS$78) -> 0 | G12: =SUMIF(Flts!F$48:F$78,UDs!$B38,Flts!$AS$48:$AS$78) -> 0 | H12: =SUMIF(Flts!E$82:E$111,UDs!$B38,Flts!$AS$82:$AS$111) -> 0 | I12: =SUMIF(Flts!F$82:F$111,UDs!$B38,Flts!$AS$82:$AS$111) -> 0 | J12: =SUMIF(Flts!E$116:E$146,UDs!$B38,Flts!$AS$116:$AS$146) -> 0 | K12: =SUMIF(Flts!F$116:F$146,UDs!$B38,Flts!$AS$116:$AS$146) -> 0 | L12: =SUMIF(Flts!E$150:E$180,UDs!$B38,Flts!$AS$150:$AS$180) -> 4 | M12: =SUMIF(Flts!F$150:F$180,UDs!$B38,Flts!$AS$150:$AS$180) -> 4 | N12: =SUMIF(Flts!E$184:E$212,UDs!$B38,Flts!$AS$184:$AS$212) -> 0 | O12: =SUMIF(Flts!F$184:F$212,UDs!$B38,Flts!$AS$184:$AS$212) -> 0 | P12: =SUMIF(Flts!E$218:E$248,UDs!$B38,Flts!$AS$218:$AS$248) -> 19 | Q12: =SUMIF(Flts!F$218:F$248,UDs!$B38,Flts!$AS$218:$AS$248) -> 12 | R12: =IF(NTri>=$R$30,SUMIF(Flts!E$252:E$281,UDs!$B38,Flts!$AS$252:$AS$281),0) -> 16 | S12: =IF(NTri>=$R$30,SUMIF(Flts!F$252:F$281,UDs!$B38,Flts!$AS$252:$AS$281),0) -> 0 | T12: =IF(NTri>=$R$30,SUMIF(Flts!E$286:E$316,UDs!$B38,Flts!$AS$286:$AS$316),0) -> 20 | U12: =IF(NTri>=$R$30,SUMIF(Flts!F$286:F$316,UDs!$B38,Flts!$AS$286:$AS$316),0) -> 0 | V12: =IF(NTri>=$R$30,SUMIF(Flts!E$320:E$349,UDs!$B38,Flts!$AS$320:$AS$349),0) -> 0 | W12: =IF(NTri>=$R$30,SUMIF(Flts!F$320:F$349,UDs!$B38,Flts!$AS$320:$AS$349),0) -> 0 | X12: =SUM(E12,G12,I12,K12,M12,O12,Q12,S12,U12,W12) -> 16 | Y12: =IF(AND(FechaInicio1Tri<=UDs!$F38, FechaFin1Tri>=UDs!$F38),(E12+G12+I12+K12)/(D12+F12+H12+J12),0%) -> 0 | Z12: =IF(AND(FechaInicio2Tri<=UDs!$F38, FechaFin2Tri>=UDs!$F38),(M12+O12+Q12)/(L12+N12+P12),0%) -> 0.69565217 | AA12: =IF(AND(FechaInicio3Tri<=UDs!$F38, FechaFin3Tri>=UDs!$F38),(S12+U12+W12)/(R12+T12+V12),0%) -> 0
B13: =IF(UDs!C39<>0,UDs!B39,IF(C13<>0,CoUDCM,0)) | C13: =IFERROR(IF(C12+UDs!C38>C12,C12+UDs!C38,0),0) -> 166 | D13: =SUMIF(Flts!E$14:E$43,UDs!$B39,Flts!$AS$14:$AS$43) -> 0 | E13: =SUMIF(Flts!F$14:F$43,UDs!$B39,Flts!$AS$14:$AS$43) -> 0 | F13: =SUMIF(Flts!E$48:E$78,UDs!$B39,Flts!$AS$48:$AS$78) -> 0 | G13: =SUMIF(Flts!F$48:F$78,UDs!$B39,Flts!$AS$48:$AS$78) -> 0 | H13: =SUMIF(Flts!E$82:E$111,UDs!$B39,Flts!$AS$82:$AS$111) -> 0 | I13: =SUMIF(Flts!F$82:F$111,UDs!$B39,Flts!$AS$82:$AS$111) -> 0 | J13: =SUMIF(Flts!E$116:E$146,UDs!$B39,Flts!$AS$116:$AS$146) -> 0 | K13: =SUMIF(Flts!F$116:F$146,UDs!$B39,Flts!$AS$116:$AS$146) -> 0 | L13: =SUMIF(Flts!E$150:E$180,UDs!$B39,Flts!$AS$150:$AS$180) -> 4 | M13: =SUMIF(Flts!F$150:F$180,UDs!$B39,Flts!$AS$150:$AS$180) -> 4 | N13: =SUMIF(Flts!E$184:E$212,UDs!$B39,Flts!$AS$184:$AS$212) -> 0 | O13: =SUMIF(Flts!F$184:F$212,UDs!$B39,Flts!$AS$184:$AS$212) -> 0 | P13: =SUMIF(Flts!E$218:E$248,UDs!$B39,Flts!$AS$218:$AS$248) -> 19 | Q13: =SUMIF(Flts!F$218:F$248,UDs!$B39,Flts!$AS$218:$AS$248) -> 12 | R13: =IF(NTri>=$R$30,SUMIF(Flts!E$252:E$281,UDs!$B39,Flts!$AS$252:$AS$281),0) -> 16 | S13: =IF(NTri>=$R$30,SUMIF(Flts!F$252:F$281,UDs!$B39,Flts!$AS$252:$AS$281),0) -> 0 | T13: =IF(NTri>=$R$30,SUMIF(Flts!E$286:E$316,UDs!$B39,Flts!$AS$286:$AS$316),0) -> 20 | U13: =IF(NTri>=$R$30,SUMIF(Flts!F$286:F$316,UDs!$B39,Flts!$AS$286:$AS$316),0) -> 0 | V13: =IF(NTri>=$R$30,SUMIF(Flts!E$320:E$349,UDs!$B39,Flts!$AS$320:$AS$349),0) -> 0 | W13: =IF(NTri>=$R$30,SUMIF(Flts!F$320:F$349,UDs!$B39,Flts!$AS$320:$AS$349),0) -> 0 | X13: =SUM(E13,G13,I13,K13,M13,O13,Q13,S13,U13,W13) -> 16 | Y13: =IF(AND(FechaInicio1Tri<=UDs!$F39, FechaFin1Tri>=UDs!$F39),(E13+G13+I13+K13)/(D13+F13+H13+J13),0%) -> 0 | Z13: =IF(AND(FechaInicio2Tri<=UDs!$F39, FechaFin2Tri>=UDs!$F39),(M13+O13+Q13)/(L13+N13+P13),0%) -> 0.69565217 | AA13: =IF(AND(FechaInicio3Tri<=UDs!$F39, FechaFin3Tri>=UDs!$F39),(S13+U13+W13)/(R13+T13+V13),0%) -> 0
B14: =IF(UDs!C40<>0,UDs!B40,IF(C14<>0,CoUDCM,0)) | C14: =IFERROR(IF(C13+UDs!C39>C13,C13+UDs!C39,0),0) -> 190 | D14: =SUMIF(Flts!E$14:E$43,UDs!$B40,Flts!$AS$14:$AS$43) -> 0 | E14: =SUMIF(Flts!F$14:F$43,UDs!$B40,Flts!$AS$14:$AS$43) -> 0 | F14: =SUMIF(Flts!E$48:E$78,UDs!$B40,Flts!$AS$48:$AS$78) -> 0 | G14: =SUMIF(Flts!F$48:F$78,UDs!$B40,Flts!$AS$48:$AS$78) -> 0 | H14: =SUMIF(Flts!E$82:E$111,UDs!$B40,Flts!$AS$82:$AS$111) -> 0 | I14: =SUMIF(Flts!F$82:F$111,UDs!$B40,Flts!$AS$82:$AS$111) -> 0 | J14: =SUMIF(Flts!E$116:E$146,UDs!$B40,Flts!$AS$116:$AS$146) -> 0 | K14: =SUMIF(Flts!F$116:F$146,UDs!$B40,Flts!$AS$116:$AS$146) -> 0 | L14: =SUMIF(Flts!E$150:E$180,UDs!$B40,Flts!$AS$150:$AS$180) -> 4 | M14: =SUMIF(Flts!F$150:F$180,UDs!$B40,Flts!$AS$150:$AS$180) -> 4 | N14: =SUMIF(Flts!E$184:E$212,UDs!$B40,Flts!$AS$184:$AS$212) -> 0 | O14: =SUMIF(Flts!F$184:F$212,UDs!$B40,Flts!$AS$184:$AS$212) -> 0 | P14: =SUMIF(Flts!E$218:E$248,UDs!$B40,Flts!$AS$218:$AS$248) -> 19 | Q14: =SUMIF(Flts!F$218:F$248,UDs!$B40,Flts!$AS$218:$AS$248) -> 12 | R14: =IF(NTri>=$R$30,SUMIF(Flts!E$252:E$281,UDs!$B40,Flts!$AS$252:$AS$281),0) -> 16 | S14: =IF(NTri>=$R$30,SUMIF(Flts!F$252:F$281,UDs!$B40,Flts!$AS$252:$AS$281),0) -> 0 | T14: =IF(NTri>=$R$30,SUMIF(Flts!E$286:E$316,UDs!$B40,Flts!$AS$286:$AS$316),0) -> 20 | U14: =IF(NTri>=$R$30,SUMIF(Flts!F$286:F$316,UDs!$B40,Flts!$AS$286:$AS$316),0) -> 0 | V14: =IF(NTri>=$R$30,SUMIF(Flts!E$320:E$349,UDs!$B40,Flts!$AS$320:$AS$349),0) -> 0 | W14: =IF(NTri>=$R$30,SUMIF(Flts!F$320:F$349,UDs!$B40,Flts!$AS$320:$AS$349),0) -> 0 | X14: =SUM(E14,G14,I14,K14,M14,O14,Q14,S14,U14,W14) -> 16 | Y14: =IF(AND(FechaInicio1Tri<=UDs!$F40, FechaFin1Tri>=UDs!$F40),(E14+G14+I14+K14)/(D14+F14+H14+J14),0%) -> 0 | Z14: =IF(AND(FechaInicio2Tri<=UDs!$F40, FechaFin2Tri>=UDs!$F40),(M14+O14+Q14)/(L14+N14+P14),0%) -> 0.69565217 | AA14: =IF(AND(FechaInicio3Tri<=UDs!$F40, FechaFin3Tri>=UDs!$F40),(S14+U14+W14)/(R14+T14+V14),0%) -> 0
B15: =IF(UDs!C41<>0,UDs!B41,IF(C15<>0,CoUDCM,0)) -> NoOk | C15: =IFERROR(IF(C14+UDs!C40>C14,C14+UDs!C40,0),0) -> 219 | D15: =SUMIF(Flts!E$14:E$43,UDs!$B41,Flts!$AS$14:$AS$43) -> 0 | E15: =SUMIF(Flts!F$14:F$43,UDs!$B41,Flts!$AS$14:$AS$43) -> 0 | F15: =SUMIF(Flts!E$48:E$78,UDs!$B41,Flts!$AS$48:$AS$78) -> 0 | G15: =SUMIF(Flts!F$48:F$78,UDs!$B41,Flts!$AS$48:$AS$78) -> 0 | H15: =SUMIF(Flts!E$82:E$111,UDs!$B41,Flts!$AS$82:$AS$111) -> 0 | I15: =SUMIF(Flts!F$82:F$111,UDs!$B41,Flts!$AS$82:$AS$111) -> 0 | J15: =SUMIF(Flts!E$116:E$146,UDs!$B41,Flts!$AS$116:$AS$146) -> 0 | K15: =SUMIF(Flts!F$116:F$146,UDs!$B41,Flts!$AS$116:$AS$146) -> 0 | L15: =SUMIF(Flts!E$150:E$180,UDs!$B41,Flts!$AS$150:$AS$180) -> 4 | M15: =SUMIF(Flts!F$150:F$180,UDs!$B41,Flts!$AS$150:$AS$180) -> 4 | N15: =SUMIF(Flts!E$184:E$212,UDs!$B41,Flts!$AS$184:$AS$212) -> 0 | O15: =SUMIF(Flts!F$184:F$212,UDs!$B41,Flts!$AS$184:$AS$212) -> 0 | P15: =SUMIF(Flts!E$218:E$248,UDs!$B41,Flts!$AS$218:$AS$248) -> 19 | Q15: =SUMIF(Flts!F$218:F$248,UDs!$B41,Flts!$AS$218:$AS$248) -> 12 | R15: =IF(NTri>=$R$30,SUMIF(Flts!E$252:E$281,UDs!$B41,Flts!$AS$252:$AS$281),0) -> 16 | S15: =IF(NTri>=$R$30,SUMIF(Flts!F$252:F$281,UDs!$B41,Flts!$AS$252:$AS$281),0) -> 0 | T15: =IF(NTri>=$R$30,SUMIF(Flts!E$286:E$316,UDs!$B41,Flts!$AS$286:$AS$316),0) -> 20 | U15: =IF(NTri>=$R$30,SUMIF(Flts!F$286:F$316,UDs!$B41,Flts!$AS$286:$AS$316),0) -> 0 | V15: =IF(NTri>=$R$30,SUMIF(Flts!E$320:E$349,UDs!$B41,Flts!$AS$320:$AS$349),0) -> 0 | W15: =IF(NTri>=$R$30,SUMIF(Flts!F$320:F$349,UDs!$B41,Flts!$AS$320:$AS$349),0) -> 0 | X15: =SUM(E15,G15,I15,K15,M15,O15,Q15,S15,U15,W15) -> 16 | Y15: =IF(AND(FechaInicio1Tri<=UDs!$F41, FechaFin1Tri>=UDs!$F41),(E15+G15+I15+K15)/(D15+F15+H15+J15),0%) -> 0 | Z15: =IF(AND(FechaInicio2Tri<=UDs!$F41, FechaFin2Tri>=UDs!$F41),(M15+O15+Q15)/(L15+N15+P15),0%) -> 0 | AA15: =IF(AND(FechaInicio3Tri<=UDs!$F41, FechaFin3Tri>=UDs!$F41),(S15+U15+W15)/(R15+T15+V15),0%) -> 0
B16: =IF(UDs!C42<>0,UDs!B42,IF(C16<>0,CoUDCM,0)) -> 0 | C16: =IFERROR(IF(C15+UDs!C41>C15,C15+UDs!C41,0),0) -> 0 | D16: =SUMIF(Flts!E$14:E$43,UDs!$B42,Flts!$AS$14:$AS$43) -> 0 | E16: =SUMIF(Flts!F$14:F$43,UDs!$B42,Flts!$AS$14:$AS$43) -> 0 | F16: =SUMIF(Flts!E$48:E$78,UDs!$B42,Flts!$AS$48:$AS$78) -> 0 | G16: =SUMIF(Flts!F$48:F$78,UDs!$B42,Flts!$AS$48:$AS$78) -> 0 | H16: =SUMIF(Flts!E$82:E$111,UDs!$B42,Flts!$AS$82:$AS$111) -> 0 | I16: =SUMIF(Flts!F$82:F$111,UDs!$B42,Flts!$AS$82:$AS$111) -> 0 | J16: =SUMIF(Flts!E$116:E$146,UDs!$B42,Flts!$AS$116:$AS$146) -> 0 | K16: =SUMIF(Flts!F$116:F$146,UDs!$B42,Flts!$AS$116:$AS$146) -> 0 | L16: =SUMIF(Flts!E$150:E$180,UDs!$B42,Flts!$AS$150:$AS$180) -> 4 | M16: =SUMIF(Flts!F$150:F$180,UDs!$B42,Flts!$AS$150:$AS$180) -> 4 | N16: =SUMIF(Flts!E$184:E$212,UDs!$B42,Flts!$AS$184:$AS$212) -> 0 | O16: =SUMIF(Flts!F$184:F$212,UDs!$B42,Flts!$AS$184:$AS$212) -> 0 | P16: =SUMIF(Flts!E$218:E$248,UDs!$B42,Flts!$AS$218:$AS$248) -> 19 | Q16: =SUMIF(Flts!F$218:F$248,UDs!$B42,Flts!$AS$218:$AS$248) -> 12 | R16: =IF(NTri>=$R$30,SUMIF(Flts!E$252:E$281,UDs!$B42,Flts!$AS$252:$AS$281),0) -> 16 | S16: =IF(NTri>=$R$30,SUMIF(Flts!F$252:F$281,UDs!$B42,Flts!$AS$252:$AS$281),0) -> 0 | T16: =IF(NTri>=$R$30,SUMIF(Flts!E$286:E$316,UDs!$B42,Flts!$AS$286:$AS$316),0) -> 20 | U16: =IF(NTri>=$R$30,SUMIF(Flts!F$286:F$316,UDs!$B42,Flts!$AS$286:$AS$316),0) -> 0 | V16: =IF(NTri>=$R$30,SUMIF(Flts!E$320:E$349,UDs!$B42,Flts!$AS$320:$AS$349),0) -> 0 | W16: =IF(NTri>=$R$30,SUMIF(Flts!F$320:F$349,UDs!$B42,Flts!$AS$320:$AS$349),0) -> 0 | X16: =SUM(E16,G16,I16,K16,M16,O16,Q16,S16,U16,W16) -> 16 | Y16: =IF(AND(FechaInicio1Tri<=UDs!$F42, FechaFin1Tri>=UDs!$F42),(E16+G16+I16+K16)/(D16+F16+H16+J16),0%) -> 0 | Z16: =IF(AND(FechaInicio2Tri<=UDs!$F42, FechaFin2Tri>=UDs!$F42),(M16+O16+Q16)/(L16+N16+P16),0%) -> 0 | AA16: =IF(AND(FechaInicio3Tri<=UDs!$F42, FechaFin3Tri>=UDs!$F42),(S16+U16+W16)/(R16+T16+V16),0%) -> 0
B17: =IF(UDs!C43<>0,UDs!B43,IF(C17<>0,CoUDCM,0)) -> 0 | C17: =IFERROR(IF(C16+UDs!C42>C16,C16+UDs!C42,0),0) -> 0 | D17: =SUMIF(Flts!E$14:E$43,UDs!$B43,Flts!$AS$14:$AS$43) -> 0 | E17: =SUMIF(Flts!F$14:F$43,UDs!$B43,Flts!$AS$14:$AS$43) -> 0 | F17: =SUMIF(Flts!E$48:E$78,UDs!$B43,Flts!$AS$48:$AS$78) -> 0 | G17: =SUMIF(Flts!F$48:F$78,UDs!$B43,Flts!$AS$48:$AS$78) -> 0 | H17: =SUMIF(Flts!E$82:E$111,UDs!$B43,Flts!$AS$82:$AS$111) -> 0 | I17: =SUMIF(Flts!F$82:F$111,UDs!$B43,Flts!$AS$82:$AS$111) -> 0 | J17: =SUMIF(Flts!E$116:E$146,UDs!$B43,Flts!$AS$116:$AS$146) -> 0 | K17: =SUMIF(Flts!F$116:F$146,UDs!$B43,Flts!$AS$116:$AS$146) -> 0 | L17: =SUMIF(Flts!E$150:E$180,UDs!$B43,Flts!$AS$150:$AS$180) -> 4 | M17: =SUMIF(Flts!F$150:F$180,UDs!$B43,Flts!$AS$150:$AS$180) -> 4 | N17: =SUMIF(Flts!E$184:E$212,UDs!$B43,Flts!$AS$184:$AS$212) -> 0 | O17: =SUMIF(Flts!F$184:F$212,UDs!$B43,Flts!$AS$184:$AS$212) -> 0 | P17: =SUMIF(Flts!E$218:E$248,UDs!$B43,Flts!$AS$218:$AS$248) -> 19 | Q17: =SUMIF(Flts!F$218:F$248,UDs!$B43,Flts!$AS$218:$AS$248) -> 12 | R17: =IF(NTri>=$R$30,SUMIF(Flts!E$252:E$281,UDs!$B43,Flts!$AS$252:$AS$281),0) -> 16 | S17: =IF(NTri>=$R$30,SUMIF(Flts!F$252:F$281,UDs!$B43,Flts!$AS$252:$AS$281),0) -> 0 | T17: =IF(NTri>=$R$30,SUMIF(Flts!E$286:E$316,UDs!$B43,Flts!$AS$286:$AS$316),0) -> 20 | U17: =IF(NTri>=$R$30,SUMIF(Flts!F$286:F$316,UDs!$B43,Flts!$AS$286:$AS$316),0) -> 0 | V17: =IF(NTri>=$R$30,SUMIF(Flts!E$320:E$349,UDs!$B43,Flts!$AS$320:$AS$349),0) -> 0 | W17: =IF(NTri>=$R$30,SUMIF(Flts!F$320:F$349,UDs!$B43,Flts!$AS$320:$AS$349),0) -> 0 | X17: =SUM(E17,G17,I17,K17,M17,O17,Q17,S17,U17,W17) -> 16 | Y17: =IF(AND(FechaInicio1Tri<=UDs!$F43, FechaFin1Tri>=UDs!$F43),(E17+G17+I17+K17)/(D17+F17+H17+J17),0%) -> 0 | Z17: =IF(AND(FechaInicio2Tri<=UDs!$F43, FechaFin2Tri>=UDs!$F43),(M17+O17+Q17)/(L17+N17+P17),0%) -> 0 | AA17: =IF(AND(FechaInicio3Tri<=UDs!$F43, FechaFin3Tri>=UDs!$F43),(S17+U17+W17)/(R17+T17+V17),0%) -> 0
B18: =IF(UDs!C44<>0,UDs!B44,IF(C18<>0,CoUDCM,0)) -> 0 | C18: =IFERROR(IF(C17+UDs!C43>C17,C17+UDs!C43,0),0) -> 0 | D18: =SUMIF(Flts!E$14:E$43,UDs!$B44,Flts!$AS$14:$AS$43) -> 0 | E18: =SUMIF(Flts!F$14:F$43,UDs!$B44,Flts!$AS$14:$AS$43) -> 0 | F18: =SUMIF(Flts!E$48:E$78,UDs!$B44,Flts!$AS$48:$AS$78) -> 0 | G18: =SUMIF(Flts!F$48:F$78,UDs!$B44,Flts!$AS$48:$AS$78) -> 0 | H18: =SUMIF(Flts!E$82:E$111,UDs!$B44,Flts!$AS$82:$AS$111) -> 0 | I18: =SUMIF(Flts!F$82:F$111,UDs!$B44,Flts!$AS$82:$AS$111) -> 0 | J18: =SUMIF(Flts!E$116:E$146,UDs!$B44,Flts!$AS$116:$AS$146) -> 0 | K18: =SUMIF(Flts!F$116:F$146,UDs!$B44,Flts!$AS$116:$AS$146) -> 0 | L18: =SUMIF(Flts!E$150:E$180,UDs!$B44,Flts!$AS$150:$AS$180) -> 4 | M18: =SUMIF(Flts!F$150:F$180,UDs!$B44,Flts!$AS$150:$AS$180) -> 4 | N18: =SUMIF(Flts!E$184:E$212,UDs!$B44,Flts!$AS$184:$AS$212) -> 0 | O18: =SUMIF(Flts!F$184:F$212,UDs!$B44,Flts!$AS$184:$AS$212) -> 0 | P18: =SUMIF(Flts!E$218:E$248,UDs!$B44,Flts!$AS$218:$AS$248) -> 19 | Q18: =SUMIF(Flts!F$218:F$248,UDs!$B44,Flts!$AS$218:$AS$248) -> 12 | R18: =IF(NTri>=$R$30,SUMIF(Flts!E$252:E$281,UDs!$B44,Flts!$AS$252:$AS$281),0) -> 16 | S18: =IF(NTri>=$R$30,SUMIF(Flts!F$252:F$281,UDs!$B44,Flts!$AS$252:$AS$281),0) -> 0 | T18: =IF(NTri>=$R$30,SUMIF(Flts!E$286:E$316,UDs!$B44,Flts!$AS$286:$AS$316),0) -> 20 | U18: =IF(NTri>=$R$30,SUMIF(Flts!F$286:F$316,UDs!$B44,Flts!$AS$286:$AS$316),0) -> 0 | V18: =IF(NTri>=$R$30,SUMIF(Flts!E$320:E$349,UDs!$B44,Flts!$AS$320:$AS$349),0) -> 0 | W18: =IF(NTri>=$R$30,SUMIF(Flts!F$320:F$349,UDs!$B44,Flts!$AS$320:$AS$349),0) -> 0 | X18: =SUM(E18,G18,I18,K18,M18,O18,Q18,S18,U18,W18) -> 16 | Y18: =IF(AND(FechaInicio1Tri<=UDs!$F44, FechaFin1Tri>=UDs!$F44),(E18+G18+I18+K18)/(D18+F18+H18+J18),0%) -> 0 | Z18: =IF(AND(FechaInicio2Tri<=UDs!$F44, FechaFin2Tri>=UDs!$F44),(M18+O18+Q18)/(L18+N18+P18),0%) -> 0 | AA18: =IF(AND(FechaInicio3Tri<=UDs!$F44, FechaFin3Tri>=UDs!$F44),(S18+U18+W18)/(R18+T18+V18),0%) -> 0
B19: =IF(UDs!C45<>0,UDs!B45,IF(C19<>0,CoUDCM,0)) -> 0 | C19: =IFERROR(IF(C18+UDs!C44>C18,C18+UDs!C44,0),0) -> 0 | D19: =SUMIF(Flts!E$14:E$43,UDs!$B45,Flts!$AS$14:$AS$43) -> 0 | E19: =SUMIF(Flts!F$14:F$43,UDs!$B45,Flts!$AS$14:$AS$43) -> 0 | F19: =SUMIF(Flts!E$48:E$78,UDs!$B45,Flts!$AS$48:$AS$78) -> 0 | G19: =SUMIF(Flts!F$48:F$78,UDs!$B45,Flts!$AS$48:$AS$78) -> 0 | H19: =SUMIF(Flts!E$82:E$111,UDs!$B45,Flts!$AS$82:$AS$111) -> 0 | I19: =SUMIF(Flts!F$82:F$111,UDs!$B45,Flts!$AS$82:$AS$111) -> 0 | J19: =SUMIF(Flts!E$116:E$146,UDs!$B45,Flts!$AS$116:$AS$146) -> 0 | K19: =SUMIF(Flts!F$116:F$146,UDs!$B45,Flts!$AS$116:$AS$146) -> 0 | L19: =SUMIF(Flts!E$150:E$180,UDs!$B45,Flts!$AS$150:$AS$180) -> 4 | M19: =SUMIF(Flts!F$150:F$180,UDs!$B45,Flts!$AS$150:$AS$180) -> 4 | N19: =SUMIF(Flts!E$184:E$212,UDs!$B45,Flts!$AS$184:$AS$212) -> 0 | O19: =SUMIF(Flts!F$184:F$212,UDs!$B45,Flts!$AS$184:$AS$212) -> 0 | P19: =SUMIF(Flts!E$218:E$248,UDs!$B45,Flts!$AS$218:$AS$248) -> 19 | Q19: =SUMIF(Flts!F$218:F$248,UDs!$B45,Flts!$AS$218:$AS$248) -> 12 | R19: =IF(NTri>=$R$30,SUMIF(Flts!E$252:E$281,UDs!$B45,Flts!$AS$252:$AS$281),0) -> 16 | S19: =IF(NTri>=$R$30,SUMIF(Flts!F$252:F$281,UDs!$B45,Flts!$AS$252:$AS$281),0) -> 0 | T19: =IF(NTri>=$R$30,SUMIF(Flts!E$286:E$316,UDs!$B45,Flts!$AS$286:$AS$316),0) -> 20 | U19: =IF(NTri>=$R$30,SUMIF(Flts!F$286:F$316,UDs!$B45,Flts!$AS$286:$AS$316),0) -> 0 | V19: =IF(NTri>=$R$30,SUMIF(Flts!E$320:E$349,UDs!$B45,Flts!$AS$320:$AS$349),0) -> 0 | W19: =IF(NTri>=$R$30,SUMIF(Flts!F$320:F$349,UDs!$B45,Flts!$AS$320:$AS$349),0) -> 0 | X19: =SUM(E19,G19,I19,K19,M19,O19,Q19,S19,U19,W19) -> 16 | Y19: =IF(AND(FechaInicio1Tri<=UDs!$F45, FechaFin1Tri>=UDs!$F45),(E19+G19+I19+K19)/(D19+F19+H19+J19),0%) -> 0 | Z19: =IF(AND(FechaInicio2Tri<=UDs!$F45, FechaFin2Tri>=UDs!$F45),(M19+O19+Q19)/(L19+N19+P19),0%) -> 0 | AA19: =IF(AND(FechaInicio3Tri<=UDs!$F45, FechaFin3Tri>=UDs!$F45),(S19+U19+W19)/(R19+T19+V19),0%) -> 0
B20: =IF(UDs!C46<>0,UDs!B46,IF(C20<>0,CoUDCM,0)) -> 0 | C20: =IFERROR(IF(C19+UDs!C45>C19,C19+UDs!C45,0),0) -> 0 | D20: =SUMIF(Flts!E$14:E$43,UDs!$B46,Flts!$AS$14:$AS$43) -> 0 | E20: =SUMIF(Flts!F$14:F$43,UDs!$B46,Flts!$AS$14:$AS$43) -> 0 | F20: =SUMIF(Flts!E$48:E$78,UDs!$B46,Flts!$AS$48:$AS$78) -> 0 | G20: =SUMIF(Flts!F$48:F$78,UDs!$B46,Flts!$AS$48:$AS$78) -> 0 | H20: =SUMIF(Flts!E$82:E$111,UDs!$B46,Flts!$AS$82:$AS$111) -> 0 | I20: =SUMIF(Flts!F$82:F$111,UDs!$B46,Flts!$AS$82:$AS$111) -> 0 | J20: =SUMIF(Flts!E$116:E$146,UDs!$B46,Flts!$AS$116:$AS$146) -> 0 | K20: =SUMIF(Flts!F$116:F$146,UDs!$B46,Flts!$AS$116:$AS$146) -> 0 | L20: =SUMIF(Flts!E$150:E$180,UDs!$B46,Flts!$AS$150:$AS$180) -> 4 | M20: =SUMIF(Flts!F$150:F$180,UDs!$B46,Flts!$AS$150:$AS$180) -> 4 | N20: =SUMIF(Flts!E$184:E$212,UDs!$B46,Flts!$AS$184:$AS$212) -> 0 | O20: =SUMIF(Flts!F$184:F$212,UDs!$B46,Flts!$AS$184:$AS$212) -> 0 | P20: =SUMIF(Flts!E$218:E$248,UDs!$B46,Flts!$AS$218:$AS$248) -> 19 | Q20: =SUMIF(Flts!F$218:F$248,UDs!$B46,Flts!$AS$218:$AS$248) -> 12 | R20: =IF(NTri>=$R$30,SUMIF(Flts!E$252:E$281,UDs!$B46,Flts!$AS$252:$AS$281),0) -> 16 | S20: =IF(NTri>=$R$30,SUMIF(Flts!F$252:F$281,UDs!$B46,Flts!$AS$252:$AS$281),0) -> 0 | T20: =IF(NTri>=$R$30,SUMIF(Flts!E$286:E$316,UDs!$B46,Flts!$AS$286:$AS$316),0) -> 20 | U20: =IF(NTri>=$R$30,SUMIF(Flts!F$286:F$316,UDs!$B46,Flts!$AS$286:$AS$316),0) -> 0 | V20: =IF(NTri>=$R$30,SUMIF(Flts!E$320:E$349,UDs!$B46,Flts!$AS$320:$AS$349),0) -> 0 | W20: =IF(NTri>=$R$30,SUMIF(Flts!F$320:F$349,UDs!$B46,Flts!$AS$320:$AS$349),0) -> 0 | X20: =SUM(E20,G20,I20,K20,M20,O20,Q20,S20,U20,W20) -> 16 | Y20: =IF(AND(FechaInicio1Tri<=UDs!$F46, FechaFin1Tri>=UDs!$F46),(E20+G20+I20+K20)/(D20+F20+H20+J20),0%) -> 0 | Z20: =IF(AND(FechaInicio2Tri<=UDs!$F46, FechaFin2Tri>=UDs!$F46),(M20+O20+Q20)/(L20+N20+P20),0%) -> 0 | AA20: =IF(AND(FechaInicio3Tri<=UDs!$F46, FechaFin3Tri>=UDs!$F46),(S20+U20+W20)/(R20+T20+V20),0%) -> 0
... B28: =IF(UDs!C54<>0,UDs!B54,IF(C28<>0,CoUDCM,0)) -> 0 | C28: =IFERROR(IF(C27+UDs!C53>C27,C27+UDs!C53,0),0) -> 0 | D28: =SUMIF(Flts!E$14:E$43,UDs!$B54,Flts!$AS$14:$AS$43) -> 0 | E28: =SUMIF(Flts!F$14:F$43,UDs!$B54,Flts!$AS$14:$AS$43) -> 0 | F28: =SUMIF(Flts!E$48:E$78,UDs!$B54,Flts!$AS$48:$AS$78) -> 0 | G28: =SUMIF(Flts!F$48:F$78,UDs!$B54,Flts!$AS$48:$AS$78) -> 0 | H28: =SUMIF(Flts!E$82:E$111,UDs!$B54,Flts!$AS$82:$AS$111) -> 0 | I28: =SUMIF(Flts!F$82:F$111,UDs!$B54,Flts!$AS$82:$AS$111) -> 0 | J28: =SUMIF(Flts!E$116:E$146,UDs!$B54,Flts!$AS$116:$AS$146) -> 0 | K28: =SUMIF(Flts!F$116:F$146,UDs!$B54,Flts!$AS$116:$AS$146) -> 0 | L28: =SUMIF(Flts!E$150:E$180,UDs!$B54,Flts!$AS$150:$AS$180) -> 4 | M28: =SUMIF(Flts!F$150:F$180,UDs!$B54,Flts!$AS$150:$AS$180) -> 4 | N28: =SUMIF(Flts!E$184:E$212,UDs!$B54,Flts!$AS$184:$AS$212) -> 0 | O28: =SUMIF(Flts!F$184:F$212,UDs!$B54,Flts!$AS$184:$AS$212) -> 0 | P28: =SUMIF(Flts!E$218:E$248,UDs!$B54,Flts!$AS$218:$AS$248) -> 19 | Q28: =SUMIF(Flts!F$218:F$248,UDs!$B54,Flts!$AS$218:$AS$248) -> 12 | R28: =IF(NTri>=$R$30,SUMIF(Flts!E$252:E$281,UDs!$B54,Flts!$AS$252:$AS$281),0) -> 16 | S28: =IF(NTri>=$R$30,SUMIF(Flts!F$252:F$281,UDs!$B54,Flts!$AS$252:$AS$281),0) -> 0 | T28: =IF(NTri>=$R$30,SUMIF(Flts!E$286:E$316,UDs!$B54,Flts!$AS$286:$AS$316),0) -> 20 | U28: =IF(NTri>=$R$30,SUMIF(Flts!F$286:F$316,UDs!$B54,Flts!$AS$286:$AS$316),0) -> 0 | V28: =IF(NTri>=$R$30,SUMIF(Flts!E$320:E$349,UDs!$B54,Flts!$AS$320:$AS$349),0) -> 0 | W28: =IF(NTri>=$R$30,SUMIF(Flts!F$320:F$349,UDs!$B54,Flts!$AS$320:$AS$349),0) -> 0 | X28: =SUM(E28,G28,I28,K28,M28,O28,Q28,S28,U28,W28) -> 16 | Y28: =IF(AND(FechaInicio1Tri<=UDs!$F54, FechaFin1Tri>=UDs!$F54),(E28+G28+I28+K28)/(D28+F28+H28+J28),0%) -> 0 | Z28: =IF(AND(FechaInicio2Tri<=UDs!$F54, FechaFin2Tri>=UDs!$F54),(M28+O28+Q28)/(L28+N28+P28),0%) -> 0 | AA28: =IF(AND(FechaInicio3Tri<=UDs!$F54, FechaFin3Tri>=UDs!$F54),(S28+U28+W28)/(R28+T28+V28),0%) -> 0
C29: ƩH. /mes | D29: =SUM(D8:D28) -> 12 | E29: =SUM(E8:E28) -> 12 | F29: =SUM(F8:F28) -> 21 | G29: =SUM(G8:G28) -> 21 | H29: =SUM(H8:H28) -> 19 | I29: =SUM(I8:I28) -> 19 | J29: =SUM(J8:J28) -> 14 | K29: =SUM(K8:K28) -> 14 | ... X29: =SUM(X8:X28) -> 367
D30: 1 | L30: 2 | R30: 3
B32: Contingencias
D34: 1er Tri. | L34: 2º Tri. | R34: 3er Tri.
B35: =Info!AD2 -> Cód.MD | C35: ΣH. MD | D35: Sep | F35: Oct | H35: Nov | J35: Dic | L35: Ene | N35: Feb | P35: Mar | R35: Abr | T35: May | V35: Jun | X35: =Info!AE2 -> Desviación
B36: =Info!AD4 -> D1 | C36: =SUM(D36,F36,H36,J36,L36,N36,P36,R36,T36,V36) -> 0 | D36: =SUMIF(Flts!$J$14:$J$43,$X36,Flts!$AS$14:$AS$43) -> 0 | F36: =SUMIF(Flts!$J$48:$J$78,$X36,Flts!$AS$48:$AS$78) -> 0 | H36: =SUMIF(Flts!$J$82:$J$111,$X36,Flts!$AS$82:$AS$111) -> 0 | J36: =SUMIF(Flts!$J$116:$J$146,$X36,Flts!$AS$116:$AS$146) -> 0 | L36: =SUMIF(Flts!$J$150:$J$180,$X36,Flts!$AS$150:$AS$180) -> 0 | N36: =SUMIF(Flts!$J$184:$J$212,$X36,Flts!$AS$184:$AS$212) -> 0 | P36: =SUMIF(Flts!$J$218:$J$248,$X36,Flts!$AS$218:$AS$248) -> 0 | R36: =SUMIF(Flts!$J$252:$J$281,$X36,Flts!$AS$252:$AS$281) -> 0 | T36: =SUMIF(Flts!$J$286:$J$316,$X36,Flts!$AS$286:$AS$316) -> 0 | V36: =SUMIF(Flts!$J$320:$J$349,$X36,Flts!$AS$320:$AS$349) -> 0 | X36: =Info!AE4 -> Baja laboral
B37: =Info!AD5 -> D2 | C37: =SUM(D37,F37,H37,J37,L37,N37,P37,R37,T37,V37) -> 0 | D37: =SUMIF(Flts!$J$14:$J$43,$X37,Flts!$AS$14:$AS$43) -> 0 | F37: =SUMIF(Flts!$J$48:$J$78,$X37,Flts!$AS$48:$AS$78) -> 0 | H37: =SUMIF(Flts!$J$82:$J$111,$X37,Flts!$AS$82:$AS$111) -> 0 | J37: =SUMIF(Flts!$J$116:$J$146,$X37,Flts!$AS$116:$AS$146) -> 0 | L37: =SUMIF(Flts!$J$150:$J$180,$X37,Flts!$AS$150:$AS$180) -> 0 | N37: =SUMIF(Flts!$J$184:$J$212,$X37,Flts!$AS$184:$AS$212) -> 0 | P37: =SUMIF(Flts!$J$218:$J$248,$X37,Flts!$AS$218:$AS$248) -> 0 | R37: =SUMIF(Flts!$J$252:$J$281,$X37,Flts!$AS$252:$AS$281) -> 0 | T37: =SUMIF(Flts!$J$286:$J$316,$X37,Flts!$AS$286:$AS$316) -> 0 | V37: =SUMIF(Flts!$J$320:$J$349,$X37,Flts!$AS$320:$AS$349) -> 0 | X37: =Info!AE5 -> Actitud
B38: =Info!AD6 -> D3 | C38: =SUM(D38,F38,H38,J38,L38,N38,P38,R38,T38,V38) -> 0 | D38: =SUMIF(Flts!$J$14:$J$43,$X38,Flts!$AS$14:$AS$43) -> 0 | F38: =SUMIF(Flts!$J$48:$J$78,$X38,Flts!$AS$48:$AS$78) -> 0 | H38: =SUMIF(Flts!$J$82:$J$111,$X38,Flts!$AS$82:$AS$111) -> 0 | J38: =SUMIF(Flts!$J$116:$J$146,$X38,Flts!$AS$116:$AS$146) -> 0 | L38: =SUMIF(Flts!$J$150:$J$180,$X38,Flts!$AS$150:$AS$180) -> 0 | N38: =SUMIF(Flts!$J$184:$J$212,$X38,Flts!$AS$184:$AS$212) -> 0 | P38: =SUMIF(Flts!$J$218:$J$248,$X38,Flts!$AS$218:$AS$248) -> 0 | R38: =SUMIF(Flts!$J$252:$J$281,$X38,Flts!$AS$252:$AS$281) -> 0 | T38: =SUMIF(Flts!$J$286:$J$316,$X38,Flts!$AS$286:$AS$316) -> 0 | V38: =SUMIF(Flts!$J$320:$J$349,$X38,Flts!$AS$320:$AS$349) -> 0 | X38: =Info!AE6 -> Ampliación
B39: =Info!AD7 -> D4 | C39: =SUM(D39,F39,H39,J39,L39,N39,P39,R39,T39,V39) -> 0 | D39: =SUMIF(Flts!$J$14:$J$43,$X39,Flts!$AS$14:$AS$43) -> 0 | F39: =SUMIF(Flts!$J$48:$J$78,$X39,Flts!$AS$48:$AS$78) -> 0 | H39: =SUMIF(Flts!$J$82:$J$111,$X39,Flts!$AS$82:$AS$111) -> 0 | J39: =SUMIF(Flts!$J$116:$J$146,$X39,Flts!$AS$116:$AS$146) -> 0 | L39: =SUMIF(Flts!$J$150:$J$180,$X39,Flts!$AS$150:$AS$180) -> 0 | N39: =SUMIF(Flts!$J$184:$J$212,$X39,Flts!$AS$184:$AS$212) -> 0 | P39: =SUMIF(Flts!$J$218:$J$248,$X39,Flts!$AS$218:$AS$248) -> 0 | R39: =SUMIF(Flts!$J$252:$J$281,$X39,Flts!$AS$252:$AS$281) -> 0 | T39: =SUMIF(Flts!$J$286:$J$316,$X39,Flts!$AS$286:$AS$316) -> 0 | V39: =SUMIF(Flts!$J$320:$J$349,$X39,Flts!$AS$320:$AS$349) -> 0 | X39: =Info!AE7 -> Retraso
B42: =Info!AG2 -> Cód.MC | C42: ΣH. MC | D42: Sep | F42: Oct | H42: Nov | J42: Dic | L42: Ene | N42: Feb | P42: Mar | R42: Abr | T42: May | V42: Jun | X42: =Info!AH2 -> Corrección
B43: =Info!AG3 -> M1 | C43: =SUM(D43,F43,H43,J43,L43,N43,P43,R43,T43,V43) -> 0 | D43: =SUMIF(Flts!$K$14:$K$43,$X43,Flts!$AS$14:$AS$43) -> 0 | F43: =SUMIF(Flts!$K$48:$K$78,$X43,Flts!$AS$48:$AS$78) -> 0 | H43: =SUMIF(Flts!$K$82:$K$111,$X43,Flts!$AS$82:$AS$111) -> 0 | J43: =SUMIF(Flts!$K$116:$K$146,$X43,Flts!$AS$116:$AS$146) -> 0 | L43: =SUMIF(Flts!$K$150:$K$180,$X43,Flts!$AS$150:$AS$180) -> 0 | N43: =SUMIF(Flts!$K$184:$K$212,$X43,Flts!$AS$184:$AS$212) -> 0 | P43: =SUMIF(Flts!$K$218:$K$248,$X43,Flts!$AS$218:$AS$248) -> 0 | R43: =SUMIF(Flts!$K$252:$K$281,$X43,Flts!$AS$252:$AS$281) -> 0 | T43: =SUMIF(Flts!$K$286:$K$316,$X43,Flts!$AS$286:$AS$316) -> 0 | V43: =SUMIF(Flts!$K$320:$K$349,$X43,Flts!$AS$320:$AS$349) -> 0 | X43: =Info!AH3 -> Trabajo personal
B44: =Info!AG4 -> M2 | C44: =SUM(D44,F44,H44,J44,L44,N44,P44,R44,T44,V44) -> 0 | D44: =SUMIF(Flts!$K$14:$K$43,$X44,Flts!$AS$14:$AS$43) -> 0 | F44: =SUMIF(Flts!$K$48:$K$78,$X44,Flts!$AS$48:$AS$78) -> 0 | H44: =SUMIF(Flts!$K$82:$K$111,$X44,Flts!$AS$82:$AS$111) -> 0 | J44: =SUMIF(Flts!$K$116:$K$146,$X44,Flts!$AS$116:$AS$146) -> 0 | L44: =SUMIF(Flts!$K$150:$K$180,$X44,Flts!$AS$150:$AS$180) -> 0 | N44: =SUMIF(Flts!$K$184:$K$212,$X44,Flts!$AS$184:$AS$212) -> 0 | P44: =SUMIF(Flts!$K$218:$K$248,$X44,Flts!$AS$218:$AS$248) -> 0 | R44: =SUMIF(Flts!$K$252:$K$281,$X44,Flts!$AS$252:$AS$281) -> 0 | T44: =SUMIF(Flts!$K$286:$K$316,$X44,Flts!$AS$286:$AS$316) -> 0 | V44: =SUMIF(Flts!$K$320:$K$349,$X44,Flts!$AS$320:$AS$349) -> 0 | X44: =Info!AH4 -> Contenido mínimo
B45: =Info!AG5 -> M3 | C45: =SUM(D45,F45,H45,J45,L45,N45,P45,R45,T45,V45) -> 0 | D45: =SUMIF(Flts!$K$14:$K$43,$X45,Flts!$AS$14:$AS$43) -> 0 | F45: =SUMIF(Flts!$K$48:$K$78,$X45,Flts!$AS$48:$AS$78) -> 0 | H45: =SUMIF(Flts!$K$82:$K$111,$X45,Flts!$AS$82:$AS$111) -> 0 | J45: =SUMIF(Flts!$K$116:$K$146,$X45,Flts!$AS$116:$AS$146) -> 0 | L45: =SUMIF(Flts!$K$150:$K$180,$X45,Flts!$AS$150:$AS$180) -> 0 | N45: =SUMIF(Flts!$K$184:$K$212,$X45,Flts!$AS$184:$AS$212) -> 0 | P45: =SUMIF(Flts!$K$218:$K$248,$X45,Flts!$AS$218:$AS$248) -> 0 | R45: =SUMIF(Flts!$K$252:$K$281,$X45,Flts!$AS$252:$AS$281) -> 0 | T45: =SUMIF(Flts!$K$286:$K$316,$X45,Flts!$AS$286:$AS$316) -> 0 | V45: =SUMIF(Flts!$K$320:$K$349,$X45,Flts!$AS$320:$AS$349) -> 0 | X45: =Info!AH5 -> Encaje futuro
AA47: =IModulo&" ("&IProfesor&")" -> FPM-it-1-0237 Infra. comunes de teleco en viviendas y edificios (Rafa Sanz)

Sheet Calnd
A1: ="Calendario académico. "&AñoInicioCurso&" - "&AñoInicioCurso+1 -> Calendario académico. 2025 - 2026 | R1: =FechaHoy -> 46099
B2: =IModulo&" ("&IProfesor&")" -> FPM-it-1-0237 Infra. comunes de teleco en viviendas y edificios (Rafa Sanz)
B4: 9 | C4: =DATE(YEAR(FechaInicio1Tri),B4,1) -> 45901 | I4: =YEAR(FechaInicio1Tri) -> 2025 | K4: 10 | L4: =DATE(YEAR(FechaInicio1Tri),K4,1) -> 45931 | R4: =YEAR(FechaInicio1Tri) -> 2025
B5: S | C5: Lun | D5: Mar | E5: Mié | F5: Jue | G5: Vie | H5: Sáb | I5: Dom | K5: S | L5: Lun | M5: Mar | N5: Mié | O5: Jue | P5: Vie | Q5: Sáb | R5: Dom
B6: =_xlfn.ISOWEEKNUM(C4) -> 36 | C6: =IF(WEEKDAY(C4,2)=1,C4,0) -> 45901 | D6: =IF(WEEKDAY(C4,2)=2, C4, IF(WEEKDAY(C4,2)<2, C6+1,0)) -> 45902 | E6: =IF(WEEKDAY(C4,2)=3, C4, IF(WEEKDAY(C4,2)<3, D6+1,0)) -> 45903 | F6: =IF(WEEKDAY(C4,2)=4, C4, IF(WEEKDAY(C4,2)<4, E6+1,0)) -> 45904 | G6: =IF(WEEKDAY(C4,2)=5, C4, IF(WEEKDAY(C4,2)<5, F6+1,0)) -> 45905 | H6: =IF(WEEKDAY(C4,2)=6, C4, IF(WEEKDAY(C4,2)<6, G6+1,0)) -> 45906 | I6: =IF(WEEKDAY(C4,2)=7, C4, IF(WEEKDAY(C4,2)<7, H6+1,0)) -> 45907 | K6: =_xlfn.ISOWEEKNUM(L4) -> 40 | L6: =IF(WEEKDAY(L4,2)=1,L4,0) -> 0 | M6: =IF(WEEKDAY(L4,2)=2, L4, IF(WEEKDAY(L4,2)<2, L6+1,0)) -> 0 | N6: =IF(WEEKDAY(L4,2)=3, L4, IF(WEEKDAY(L4,2)<3, M6+1,0)) -> 45931 | O6: =IF(WEEKDAY(L4,2)=4, L4, IF(WEEKDAY(L4,2)<4, N6+1,0)) -> 45932 | P6: =IF(WEEKDAY(L4,2)=5, L4, IF(WEEKDAY(L4,2)<5, O6+1,0)) -> 45933 | Q6: =IF(WEEKDAY(L4,2)=6, L4, IF(WEEKDAY(L4,2)<6, P6+1,0)) -> 45934 | R6: =IF(WEEKDAY(L4,2)=7, L4, IF(WEEKDAY(L4,2)<7, Q6+1,0)) -> 45935
C7: =IFERROR(_xlfn.XLOOKUP(C6,Flts!$I$14:$I$349,Flts!$C$14:$C$349),0) -> 0 | D7: =IFERROR(_xlfn.XLOOKUP(D6,Flts!$I$14:$I$349,Flts!$C$14:$C$349),0) -> 0 | E7: =IFERROR(_xlfn.XLOOKUP(E6,Flts!$I$14:$I$349,Flts!$C$14:$C$349),0) -> 0 | F7: =IFERROR(_xlfn.XLOOKUP(F6,Flts!$I$14:$I$349,Flts!$C$14:$C$349),0) -> 0 | G7: =IFERROR(_xlfn.XLOOKUP(G6,Flts!$I$14:$I$349,Flts!$C$14:$C$349),0) -> 0 | H7: =IFERROR(_xlfn.XLOOKUP(H6,Flts!$I$14:$I$349,Flts!$C$14:$C$349),0) -> 0 | I7: =IFERROR(_xlfn.XLOOKUP(I6,Flts!$I$14:$I$349,Flts!$C$14:$C$349),0) -> 0 | L7: =IFERROR(_xlfn.XLOOKUP(L6,Flts!$I$14:$I$349,Flts!$C$14:$C$349),0) -> 0 | M7: =IFERROR(_xlfn.XLOOKUP(M6,Flts!$I$14:$I$349,Flts!$C$14:$C$349),0) -> 0 | N7: =IFERROR(_xlfn.XLOOKUP(N6,Flts!$I$14:$I$349,Flts!$C$14:$C$349),0) -> 0 | O7: =IFERROR(_xlfn.XLOOKUP(O6,Flts!$I$14:$I$349,Flts!$C$14:$C$349),0) -> 0 | P7: =IFERROR(_xlfn.XLOOKUP(P6,Flts!$I$14:$I$349,Flts!$C$14:$C$349),0) -> 0 | Q7: =IFERROR(_xlfn.XLOOKUP(Q6,Flts!$I$14:$I$349,Flts!$C$14:$C$349),0) -> 0 | R7: =IFERROR(_xlfn.XLOOKUP(R6,Flts!$I$14:$I$349,Flts!$C$14:$C$349),0) -> 0
C8: =IFERROR(_xlfn.XLOOKUP(C6,Flts!$I$14:$I$349,Flts!$D$14:$D$349),0) -> 0 | D8: =IFERROR(_xlfn.XLOOKUP(D6,Flts!$I$14:$I$349,Flts!$D$14:$D$349),0) -> 0 | E8: =IFERROR(_xlfn.XLOOKUP(E6,Flts!$I$14:$I$349,Flts!$D$14:$D$349),0) -> 0 | F8: =IFERROR(_xlfn.XLOOKUP(F6,Flts!$I$14:$I$349,Flts!$D$14:$D$349),0) -> FCT+Pry. ExtraOrd | G8: =IFERROR(_xlfn.XLOOKUP(G6,Flts!$I$14:$I$349,Flts!$D$14:$D$349),0) -> 0 | H8: =IFERROR(_xlfn.XLOOKUP(H6,Flts!$I$14:$I$349,Flts!$D$14:$D$349),0) -> 0 | I8: =IFERROR(_xlfn.XLOOKUP(I6,Flts!$I$14:$I$349,Flts!$D$14:$D$349),0) -> 0 | L8: =IFERROR(_xlfn.XLOOKUP(L6,Flts!$I$14:$I$349,Flts!$D$14:$D$349),0) -> 0 | M8: =IFERROR(_xlfn.XLOOKUP(M6,Flts!$I$14:$I$349,Flts!$D$14:$D$349),0) -> 0 | N8: =IFERROR(_xlfn.XLOOKUP(N6,Flts!$I$14:$I$349,Flts!$D$14:$D$349),0) -> 0 | O8: =IFERROR(_xlfn.XLOOKUP(O6,Flts!$I$14:$I$349,Flts!$D$14:$D$349),0) -> 0 | P8: =IFERROR(_xlfn.XLOOKUP(P6,Flts!$I$14:$I$349,Flts!$D$14:$D$349),0) -> 0 | Q8: =IFERROR(_xlfn.XLOOKUP(Q6,Flts!$I$14:$I$349,Flts!$D$14:$D$349),0) -> 0 | R8: =IFERROR(_xlfn.XLOOKUP(R6,Flts!$I$14:$I$349,Flts!$D$14:$D$349),0) -> 0
C9: =IFERROR(_xlfn.XLOOKUP(C6,Flts!$I$14:$I$349,Flts!$E$14:$E$349),0) -> 0 | D9: =IFERROR(_xlfn.XLOOKUP(D6,Flts!$I$14:$I$349,Flts!$E$14:$E$349),0) -> 0 | E9: =IFERROR(_xlfn.XLOOKUP(E6,Flts!$I$14:$I$349,Flts!$E$14:$E$349),0) -> 0 | F9: =IFERROR(_xlfn.XLOOKUP(F6,Flts!$I$14:$I$349,Flts!$E$14:$E$349),0) -> 0 | G9: =IFERROR(_xlfn.XLOOKUP(G6,Flts!$I$14:$I$349,Flts!$E$14:$E$349),0) -> 0 | L9: =IFERROR(_xlfn.XLOOKUP(L6,Flts!$I$14:$I$349,Flts!$E$14:$E$349),0) -> 0 | M9: =IFERROR(_xlfn.XLOOKUP(M6,Flts!$I$14:$I$349,Flts!$E$14:$E$349),0) -> 0 | N9: =IFERROR(_xlfn.XLOOKUP(N6,Flts!$I$14:$I$349,Flts!$E$14:$E$349),0) -> UD01 | O9: =IFERROR(_xlfn.XLOOKUP(O6,Flts!$I$14:$I$349,Flts!$E$14:$E$349),0) -> UD01 | P9: =IFERROR(_xlfn.XLOOKUP(P6,Flts!$I$14:$I$349,Flts!$E$14:$E$349),0) -> UD01
B10: =_xlfn.ISOWEEKNUM(C10) -> 37 | C10: =I6+1 -> 45908 | D10: =C10+1 -> 45909 | E10: =D10+1 -> 45910 | F10: =E10+1 -> 45911 | G10: =F10+1 -> 45912 | H10: =G10+1 -> 45913 | I10: =H10+1 -> 45914 | K10: =_xlfn.ISOWEEKNUM(L10) -> 41 | L10: =R6+1 -> 45936 | M10: =L10+1 -> 45937 | N10: =M10+1 -> 45938 | O10: =N10+1 -> 45939 | P10: =O10+1 -> 45940 | Q10: =P10+1 -> 45941 | R10: =Q10+1 -> 45942
C11: =IFERROR(_xlfn.XLOOKUP(C10,Flts!$I$14:$I$349,Flts!$C$14:$C$349),0) -> 0 | D11: =IFERROR(_xlfn.XLOOKUP(D10,Flts!$I$14:$I$349,Flts!$C$14:$C$349),0) -> 0 | E11: =IFERROR(_xlfn.XLOOKUP(E10,Flts!$I$14:$I$349,Flts!$C$14:$C$349),0) -> 0 | F11: =IFERROR(_xlfn.XLOOKUP(F10,Flts!$I$14:$I$349,Flts!$C$14:$C$349),0) -> 0 | G11: =IFERROR(_xlfn.XLOOKUP(G10,Flts!$I$14:$I$349,Flts!$C$14:$C$349),0) -> 0 | H11: =IFERROR(_xlfn.XLOOKUP(H10,Flts!$I$14:$I$349,Flts!$C$14:$C$349),0) -> 0 | I11: =IFERROR(_xlfn.XLOOKUP(I10,Flts!$I$14:$I$349,Flts!$C$14:$C$349),0) -> 0 | L11: =IFERROR(_xlfn.XLOOKUP(L10,Flts!$I$14:$I$349,Flts!$C$14:$C$349),0) -> 0 | M11: =IFERROR(_xlfn.XLOOKUP(M10,Flts!$I$14:$I$349,Flts!$C$14:$C$349),0) -> 0 | N11: =IFERROR(_xlfn.XLOOKUP(N10,Flts!$I$14:$I$349,Flts!$C$14:$C$349),0) -> 0 | O11: =IFERROR(_xlfn.XLOOKUP(O10,Flts!$I$14:$I$349,Flts!$C$14:$C$349),0) -> 0 | P11: =IFERROR(_xlfn.XLOOKUP(P10,Flts!$I$14:$I$349,Flts!$C$14:$C$349),0) -> Pilares | Q11: =IFERROR(_xlfn.XLOOKUP(Q10,Flts!$I$14:$I$349,Flts!$C$14:$C$349),0) -> 0 | R11: =IFERROR(_xlfn.XLOOKUP(R10,Flts!$I$14:$I$349,Flts!$C$14:$C$349),0) -> 0
C12: =IFERROR(_xlfn.XLOOKUP(C10,Flts!$I$14:$I$349,Flts!$D$14:$D$349),0) -> 0 | D12: =IFERROR(_xlfn.XLOOKUP(D10,Flts!$I$14:$I$349,Flts!$D$14:$D$349),0) -> 0 | E12: =IFERROR(_xlfn.XLOOKUP(E10,Flts!$I$14:$I$349,Flts!$D$14:$D$349),0) -> 0 | F12: =IFERROR(_xlfn.XLOOKUP(F10,Flts!$I$14:$I$349,Flts!$D$14:$D$349),0) -> Presentación | G12: =IFERROR(_xlfn.XLOOKUP(G10,Flts!$I$14:$I$349,Flts!$D$14:$D$349),0) -> Inicio clases | H12: =IFERROR(_xlfn.XLOOKUP(H10,Flts!$I$14:$I$349,Flts!$D$14:$D$349),0) -> 0 | I12: =IFERROR(_xlfn.XLOOKUP(I10,Flts!$I$14:$I$349,Flts!$D$14:$D$349),0) -> 0 | L12: =IFERROR(_xlfn.XLOOKUP(L10,Flts!$I$14:$I$349,Flts!$D$14:$D$349),0) -> 0 | M12: =IFERROR(_xlfn.XLOOKUP(M10,Flts!$I$14:$I$349,Flts!$D$14:$D$349),0) -> 0 | N12: =IFERROR(_xlfn.XLOOKUP(N10,Flts!$I$14:$I$349,Flts!$D$14:$D$349),0) -> 0 | O12: =IFERROR(_xlfn.XLOOKUP(O10,Flts!$I$14:$I$349,Flts!$D$14:$D$349),0) -> 0 | P12: =IFERROR(_xlfn.XLOOKUP(P10,Flts!$I$14:$I$349,Flts!$D$14:$D$349),0) -> 0 | Q12: =IFERROR(_xlfn.XLOOKUP(Q10,Flts!$I$14:$I$349,Flts!$D$14:$D$349),0) -> 0 | R12: =IFERROR(_xlfn.XLOOKUP(R10,Flts!$I$14:$I$349,Flts!$D$14:$D$349),0) -> 0
C13: =IFERROR(_xlfn.XLOOKUP(C10,Flts!$I$14:$I$349,Flts!$E$14:$E$349),0) -> 0 | D13: =IFERROR(_xlfn.XLOOKUP(D10,Flts!$I$14:$I$349,Flts!$E$14:$E$349),0) -> 0 | E13: =IFERROR(_xlfn.XLOOKUP(E10,Flts!$I$14:$I$349,Flts!$E$14:$E$349),0) -> 0 | F13: =IFERROR(_xlfn.XLOOKUP(F10,Flts!$I$14:$I$349,Flts!$E$14:$E$349),0) -> 0 | G13: =IFERROR(_xlfn.XLOOKUP(G10,Flts!$I$14:$I$349,Flts!$E$14:$E$349),0) -> 0 | L13: =IFERROR(_xlfn.XLOOKUP(L10,Flts!$I$14:$I$349,Flts!$E$14:$E$349),0) -> UD01 | M13: =IFERROR(_xlfn.XLOOKUP(M10,Flts!$I$14:$I$349,Flts!$E$14:$E$349),0) -> UD01 | N13: =IFERROR(_xlfn.XLOOKUP(N10,Flts!$I$14:$I$349,Flts!$E$14:$E$349),0) -> UD01 | O13: =IFERROR(_xlfn.XLOOKUP(O10,Flts!$I$14:$I$349,Flts!$E$14:$E$349),0) -> UD01 | P13: =IFERROR(_xlfn.XLOOKUP(P10,Flts!$I$14:$I$349,Flts!$E$14:$E$349),0) -> 0
